Workbook

Sheet Início
A1: Elaborado por: Chefe Fernando Mendes (contato: fernando.mendes@escoteiros.org.br)
A2: OBSERVAÇÕES IMPORTANTES!
A3: ESTE NÃO É UM DOCUMENTO OFICIAL DA UNIÃO DOS ESCOTEIROS DO BRASIL (UEB)
A4: As "equivalências" apontadas nesta planilha foram feitas por observações pessoais e subjetivas do criador desta planilha e podem não refletir o entendimento de outros escotistas, os quais farão as conversões/equiparações da progressão dos seus jovens conforme seus próprios entendimentos e critérios.
A5: Por se tratar de equiparações subjetivas e individualizadas para cada jovem, o escotista pode (e deve!) realizar outras alterações/equiparações conforme suas necessidades/entendimento, motivo pelo qual a presente planilha caso utilizada deve ser tratada apenas como um documento de orientação, e não como a verdade absoluta.
A6: Esta planilha só realiza equivalências dos itens da modalidade básica. (Os itens de progressão específicos das modalidades do Ar e do Mar, não foram verificados)
A7: Foi observado que alguns itens de progressão do programa atualizado "equivalem" à íntegra ou são muito similares a 100% de determinadas competências do programa anterior, portanto alguns itens do programa atualizado somente serão considerados OK nesta planilha caso o jovem tenha atingido 100% da competência do programa anterior
A8: As especialidades sofreram modificações no novo programa, algumas foram extintas e outras foram criadas. As especialidades de VOLEI e HANDEBOL, por exemplo, não existem mais. Contundo foi criada a especialidade ESPORTES DE QUADRA, que para esta planilha são equivalentes, ou seja, se o(a) jovem possui especialidade de volei ou handebol esta planilha valida o item de progressão como se tivesse a especialidade de esportes de quadra. Da mesma forma ocorre com as especialidades de GINÁSTIVA RITMICA e GINÁSTICA ARTÍSTICA, que não existem mais, porém existe a agora a especialidade de GINÁSTICAS.
A10: COMO UTILIZAR ESTA PLANILHA EM APENAS 5 PASSOS:
A12: 1º - Você precisará de um novo arquivo/planilha para cada jovem, portanto sugere-se deixar o arquivo original salvo em seu computador para utilizar como modelo. Na aba "Dados do Jovem" insira nas células em azul claro na coluna "B" o nome do(a) jovem e selecione a progressão em que ele(a) se encontra no programa antigo. Siga para o próximo passo.
A14: 2º - Na aba "PISTAS E TRILHAS" escolha na caixa de seleção se o(a) jovem já realizou 100% dos itens, neste caso a planilha preencherá os dados automaticamente OU caso não tenha realizado 100% dos itens: digite apenas o numeral "1" (sem as aspas) nas células em azul claro na coluna "A", ao lado dos itens que já foram realizados pelo jovem no programa antigo. Acesse o mAPPa ou o PAXTU para buscar estas informações. Na aba "RUMO E TRAVESSIA" digite apenas o numeral "1" (sem as aspas) nas células em azul claro na coluna "A", ao lado dos itens que já foram realizados pelo jovem no programa antigo. Acesse o mAPPa ou o PAXTU para buscar estas informações. Após inserir as informações nas abas "PISTAS E TRILHA" e "RUMO E TRAVESSIA" e siga para o próximo passo.
A16: 3º - Na aba "ESPECIALIDADES" digite apenas o numeral "1" (sem as aspas) nas células em azul claro ao lado do nome das insígnias e/ou distintivos e/ou respectivas especialidades já conquistadas pelo jovem. Feito isso siga para o próximo passo.
... A22: Eu não concordo com uma ou mais equivalências feitas automaticamnte pela planilha E/OU quero validar um item que acabei de conversar com o(a) jovem para chegar na progressar correta? Como fazer? Se você não concorda com a equivalência automática feita pela planilha você pode desmarcar o item manualmente inserindo o numeral "-1" (um negativo, sem aspas) na célula em azul claro ao lado direito do respectivo item. Feito isto o item não será considerado cumprido pelo(a) jovem. Para validar manualmente um item de progressão basta digitar o numeral "1" (sem aspas) na célula em azul claro ao lado direito do respectivo item. Feito isto o item será validado e considerado como cumprido. Caso resolva retornar para o sistema automatizado pela planilha, basta deixar novamente a célula em azul claro sem nenhum preenchimento (vazia). Feito isso a planilha voltará a considerar apenas a conversão/equiparação automática daquele item.

Sheet Dados do Jovem
A1: Nome do(a) jovem: | C1: Selecione aqui progressão
A2: Progressão programa antigo: | B2: Selecione aqui progressão | C2: PISTAS
C3: TRILHA
A4: Blocos educacionais concluídos: | B4: ='Habilidades para a Vida'!I3+'Meio Ambiente'!I3+'Paz e Desenvolvimento'!G3+'Saúde e Bem Estar'!G3 -> 0 | C4: RUMO
C5: TRAVESSIA
A6: Progressão no novo programa: | B6: =IF(B4<=3,"PISTAS",IF(B4<=7,"TRILHA",IF(B4<=12,"RUMO","TRAVESSIA"))) -> PISTAS
B7: =IF(B6=B2,"Equipação OK","Necessário adaptar itens") -> Necessário adaptar itens

Sheet Pistas e Trilha
C1: PISTAS E TRILHA
C2: Selecione na célula abaixo: o(a) jovem já concluiu todos os itens de Pistas e Trilhas?
C3: Não concluiu 100% dos itens | E3: Sim, já concluiu 100% dos itens
C4: =IF(C3="Não concluiu 100% dos itens","Marcar abaixo apenas o numeral 1 (sem as aspas) nas células em azul claro na coluna A, ao lado dos itens que já foram realizados pelo jovem no programa antigo","OK, todos os itens desta aba foram marcados automaticamente") -> Marcar abaixo apenas o numeral 1 (sem as aspas) nas células em azul claro na coluna A, ao lado dos itens que já foram realizados pelo jovem no programa antigo | E4: Não concluiu 100% dos itens
C6: FÍSICO
A7: =IF(A11=3,1,0) -> 0 | C7: Percebo que meu corpo está mudando, e faço atividades que o ajudam a ser forte e sadio, evitando aquilo que pode me fazer mal.
A8: =IF($C$3="Sim, já concluiu 100% dos itens",1,0) -> 0 | B8: 1 | C8: Participar de pelo menos 5 atividades ao ar livre da patrulha (jornadas, excursões, acampamentos de patrulha ou tropa) utilizando normas de baixo impacto ambiental.
A9: =IF($C$3="Sim, já concluiu 100% dos itens",1,0) -> 0 | B9: 2 | C9: Conhecer e aplicar normas de limpeza no tratamento e na conservação de alimentos nas atividades de patrulha.
A10: =IF($C$3="Sim, já concluiu 100% dos itens",1,0) -> 0 | B10: 3 | C10: Aferir seu passo duplo, conhecer as medidas de seu corpo e aplicar-las em avaliações e medições.
A11: =SUM(A8:A10) -> 0
A12: =IF(A17=4,1,0) -> 0 | C12: Participo das atividades organizadas por minha patrulha cuidando para não colocar em risco minha saúde e a de meus companheiros.
A13: =IF($C$3="Sim, já concluiu 100% dos itens",1,0) -> 0 | B13: 4 | C13: Conhecer os elementos que compõem a caixa de primeiros socorros da patrulha.
A14: =IF($C$3="Sim, já concluiu 100% dos itens",1,0) -> 0 | B14: 5 | C14: Conhecer as ações iniciais que devem ser tomadas num acidente e saber como cuidar de ferimentos leves; bandagens e transporte de feridos, pequenos cortes e insetos
A15: =IF($C$3="Sim, já concluiu 100% dos itens",1,0) -> 0 | B15: 6 | C15: Aplicar medidas de segurança nas atividades de patrulha e tropa.
A16: =IF($C$3="Sim, já concluiu 100% dos itens",1,0) -> 0 | B16: 7 | C16: Saber como prevenir os males da exposição ao sol: insolação, desidratação, queimaduras, câncer de pele.
A17: =SUM(A13:A16) -> 0
A18: =IF(A23=4,1,0) -> 0 | C18: Mantenho limpo e arrumado o ambiente em que faço minhas coisas, e cuido da minha higiene e apresentação pessoal.
A19: =IF($C$3="Sim, já concluiu 100% dos itens",1,0) -> 0 | B19: 8 | C19: Manter hábitos de higiene individual, demonstrar cuidado com o vestuário ou uniforme escoteiro e utilizar corretamente os distintivos e emblemas.
A20: =IF($C$3="Sim, já concluiu 100% dos itens",1,0) -> 0 | B20: 9 | C20: Classificar o lixo em diferentes categorias e saber como tratar os diferentes tipos de resíduos de acampamentos ou excursões utilizando “engenhocas” para melhorar a higiene e o conforto nos acampamentos.
A21: =IF($C$3="Sim, já concluiu 100% dos itens",1,0) -> 0 | B21: 10 | C21: Participar da manutenção do canto de patrulha, conhecer os materiais de sua patrulha e contribuir para a sua conservação, organização e limpeza.
A22: =IF($C$3="Sim, já concluiu 100% dos itens",1,0) -> 0 | B22: 11 | C22: Montar corretamente uma mochila para um acampamento de 3 dias e manter seu equipamento pessoal em bom estado.
A23: =SUM(A19:A22) -> 0
A24: =IF(A29=4,1,0) -> 0 | C24: Como alimentos saudáveis, nas horas certas, e cuido da limpeza ao preparar refeições.
A25: =IF($C$3="Sim, já concluiu 100% dos itens",1,0) -> 0 | B25: 12 | C25: Montar o cardápio de uma jornada e durante as atividades de sua patrulha, fazer as refeições de maneira equilibrada.
A26: =IF($C$3="Sim, já concluiu 100% dos itens",1,0) -> 0 | B26: 13 | C26: Colaborar na elaboração de alimentos (como cozinheiro ou copeiro) em pelo menos três atividades ao ar livre da patrulha; (jornadas, excursões ou acampamento de patrulha).
A27: =IF($C$3="Sim, já concluiu 100% dos itens",1,0) -> 0 | B27: 14 | C27: Montar uma solução para purificação de água em acampamentos
A28: =IF($C$3="Sim, já concluiu 100% dos itens",1,0) -> 0 | B28: 15 | C28: Utilizar diversos tipos de fogos de acampamento, de maneira adequada e segura.
A29: =SUM(A25:A28) -> 0
A30: =IF(A34=3,1,0) -> 0 | C30: Dedico ao estudo tempo suficiente, e uso meu tempo livre para participar de atividades recreativas e variadas.
A31: =IF($C$3="Sim, já concluiu 100% dos itens",1,0) -> 0 | B31: 16 | C31: Organizar seu tempo utilizando uma agenda ou instrumento similar.
A32: =IF($C$3="Sim, já concluiu 100% dos itens",1,0) -> 0 | B32: 17 | C32: Realizar, dentro do prazo, as suas tarefas escolares
A33: =IF($C$3="Sim, já concluiu 100% dos itens",1,0) -> 0 | B33: 18 | C33: Frequentar regularmente as atividades e reuniões da sua patrulha e da tropa.
A34: =SUM(A31:A33) -> 0
A35: =IF(A38=2,1,0) -> 0 | C35: Pratico atividades físicas regularmente e participo de muitos jogos, respeitando as suas regras e os demais participantes.
A36: =IF($C$3="Sim, já concluiu 100% dos itens",1,0) -> 0 | B36: 19 | C36: Realizar regularmente uma atividade física ou o esporte que escolheu.
A37: =IF($C$3="Sim, já concluiu 100% dos itens",1,0) -> 0 | B37: 20 | C37: Participar de diversos jogos com sua patrulha e tropa respeitando as regras e aos demais participantes.
A38: =SUM(A36:A37) -> 0
C39: INTELECTUAL
A40: =IF(A44=3,1,0) -> 0 | C40: Interesso-me pelo que se passa a minha volta e estou sempre disposto a aprender coisas novas.
A41: =IF($C$3="Sim, já concluiu 100% dos itens",1,0) -> 0 | B41: 21 | C41: Traçar e seguir sinais de pista em um percurso de pelo menos 500 metros em área de campo, e pelo menos 1.000 metros em área urbana.
...

Sheet Rumo e Travessia
C1: RUMO E TRAVESSIA
C2: Marcar abaixo apenas o numeral "1" (sem as aspas) nas células em azul claro na coluna "A", ao lado dos itens que já foram realizados pelo jovem no programa antigo
C4: FÍSICO
A5: =IF(A9=3,1,0) -> 0 | C5: Respeito meu corpo e o dos outros, entendo as mudanças que estão acontecendo, como me afetam e procuro superar as dificuldades físicas próprias de meu crescimento.
B6: 1 | C6: Participar de pelo menos 5 atividades ao ar livre da patrulha (acampamentos ou excursões) utilizando normas de baixo impacto ambiental.
B7: 2 | C7: Saber explicar as mudanças que estão acontecendo no seu corpo; conhecer os males da anorexia, bulimia, os perigos do álcool e cigarro e manter hábitos de higiene pessoal.
B8: 3 | C8: Participar de uma Jornada de Travessia.
A9: =SUM(A6:A8) -> 0
A10: =IF(A15=4,1,0) -> 0 | C10: Sei o que fazer em caso de uma enfermidade ou acidente.
B11: 4 | C11: Reconhecer os tipos mais comuns de animais venenosos e peçonhentos de sua região.
B12: 5 | C12: Manter em dia os elementos que compõem a caixa de primeiros socorros da patrulha.
B13: 6 | C13: Aplicar medidas gerais de segurança em caso de acidentes, e saber determinar a ordem de prioridades quando assistir a um acidente e utilizar distintas técnicas para o transporte de feridos.
B14: 7 | C14: Saber agir em casos de hemorragia
A15: =SUM(A11:A14) -> 0
A16: =IF(A21=4,1,0) -> 0 | C16: Mantenho minhas coisas limpas e organizadas, cuido dos lugares que visito e da minha apresentação pessoal.
B17: 8 | C17: Participar de uma atividade de limpeza e organização do canto de patrulha (em sede).
B18: 9 | C18: Propor e executar uma atividade de melhoria em algum local visitado pela patrulha em acampamentos e manter em ordem seu quarto e objetos pessoais.
B19: 10 | C19: Demonstrar cuidado com seu vestuário ou uniforme escoteiro e costurar os seus distintivos e insígnias
B20: 11 | C20: Montar corretamente uma mochila para um acampamento de cinco dias e manter o equipamentos de sua patrulha em bom estado.
A21: =SUM(A17:A20) -> 0
A22: =IF(A26=3,1,0) -> 0 | C22: Sei preparar uma refeição com ordem e limpeza, considerando os valores dos alimentos e suas contribuições para o saúde.
B23: 12 | C23: Preparar cinco refeições para sua patrulha, incluindo a preparação de um prato quente e de uma sobremesa sendo três refeições em fogueira ou fogão de campo.
B24: 13 | C24: Montar o cardápio de um acampamento de patrulha de fim de semana e fazer as refeições de maneira equilibrada, durante as atividades de patrulha.
B25: 14 | C25: Cozinhar ao ar livre sem utensílios (comida mateira), respeitando as normas de limpeza
A26: =SUM(A23:A25) -> 0
A27: =IF(A32=4,1,0) -> 0 | C27: Sei distribuir meu tempo para atividades de estudo, convivência familiar, com amigos e sei escolher o que fazer no meu tempo livre.
B28: 15 | C28: Organizar suas atividades em um calendário semanal.
B29: 16 | C29: Classificar suas atividades segundo um critério de prioridades.
B30: 17 | C30: Participar regularmente das atividades e reuniões de sua patrulha, contribuindo com ideias e sugestões para as atividades.
B31: 18 | C31: Desenvolver um passatempo ou hobbie.
A32: =SUM(A28:A31) -> 0
A33: =IF(A36=2,1,0) -> 0 | C33: Me esforço para melhorar meu desempenho nas atividades físicas que pratico
B34: 19 | C34: Realizar regularmente uma atividade física ou esporte, demonstrando progresso em seu desempenho
B35: 20 | C35: Participar de diversos jogos com outros grupos escoteiros, respeitando as regras e os demais participantes.
A36: =SUM(A34:A35) -> 0
C37: INTELECTUAL
A38: =IF(A43=4,1,0) -> 0 | C38: Procuro ampliar meus conhecimentos e sei refletir criticamente sobre os fatos que ocorrem em minha volta, e me interesso pela leitura de diversos temas.
B39: 21 | C39: Realizar previsão do tempo por indícios naturais e por instrumentos.
B40: 22 | C40: Traçar e seguir sinais de pista em um percurso de, pelo menos, 1 km no campo ou 2 km em área urbana
B41: 23 | C41: Orientar-se utilizando recursos naturais (estrelas, método do relógio), assim como usando uma bússola e um mapa
...

Sheet Especialidades ou Insígnias
A1: INSTRUÇÕES: apenas digite o numeral "1" (sem aspas) na célula em azul claro ao lado do nome da especialidade, ou Insíginia já conquistada pelo jovem no programa antigo
A3: pare o mouse/cursor aqui para abrir informações adicionais
B5: Prog. Antigo | F5: Prog. Novo
A6: Especialidade / Insígnia Especial | B6: Nível 1 | C6: Nível 2 | D6: Nível 3 | F6: Nível 1 | G6: Nível 2
A7: Acampamento | F7: =IF(B7>0,1,0) -> 0 | G7: =IF(OR(C7>0,D7>0),"1","") | H7: =IF(OR(C7=1,D7=1),1,0) -> 0
A8: Acampamento de Mínimo Impacto | F8: =IF(B8>0,1,0) -> 0 | G8: =IF(OR(C8>0,D8>0),"1","") | H8: =IF(OR(C8=1,D8=1),1,0) -> 0
A9: Administração | F9: =IF(B9>0,1,0) -> 0 | G9: =IF(OR(C9>0,D9>0),"1","") | H9: =IF(OR(C9=1,D9=1),1,0) -> 0
A10: Aeromodelismo | F10: =IF(B10>0,1,0) -> 0 | G10: =IF(OR(C10>0,D10>0),"1","") | H10: =IF(OR(C10=1,D10=1),1,0) -> 0
A11: Agricultura | F11: =IF(B11>0,1,0) -> 0 | G11: =IF(OR(C11>0,D11>0),"1","") | H11: =IF(OR(C11=1,D11=1),1,0) -> 0
A12: Alfabetização | F12: =IF(B12>0,1,0) -> 0 | G12: =IF(OR(C12>0,D12>0),"1","") | H12: =IF(OR(C12=1,D12=1),1,0) -> 0
A13: Almoxarifado | F13: =IF(B13>0,1,0) -> 0 | G13: =IF(OR(C13>0,D13>0),"1","") | H13: =IF(OR(C13=1,D13=1),1,0) -> 0
A14: Anatomia Humana | F14: =IF(B14>0,1,0) -> 0 | G14: =IF(OR(C14>0,D14>0),"1","") | H14: =IF(OR(C14=1,D14=1),1,0) -> 0
A15: Animação da Fé | F15: =IF(B15>0,1,0) -> 0 | G15: =IF(OR(C15>0,D15>0),"1","") | H15: =IF(OR(C15=1,D15=1),1,0) -> 0
A16: Animais Peçonhentos (Equiparação com a nova: Animais Venenosos e Peçonhentos) | F16: =IF(B16>0,1,0) -> 0 | G16: =IF(OR(C16>0,D16>0),"1","") | H16: =IF(OR(C16=1,D16=1),1,0) -> 0
A17: Anime | F17: =IF(B17>0,1,0) -> 0 | G17: =IF(OR(C17>0,D17>0),"1","") | H17: =IF(OR(C17=1,D17=1),1,0) -> 0
A18: Aquariofilia | F18: =IF(B18>0,1,0) -> 0 | G18: =IF(OR(C18>0,D18>0),"1","") | H18: =IF(OR(C18=1,D18=1),1,0) -> 0
... A114: Expressão Musical | F114: =IF(B114>0,1,0) -> 0 | G114: =IF(OR(C114>0,D114>0),"1","") | H114: =IF(OR(C114=1,D114=1),1,0) -> 0
A115: Explorador | F115: =IF(B115>0,1,0) -> 0
A116: Faixa do Cidadão | F116: =IF(B116>0,1,0) -> 0 | G116: =IF(OR(C116>0,D116>0),"1","") | H116: =IF(OR(C116=1,D116=1),1,0) -> 0
A117: Ferramentas de Corte | F117: =IF(B117>0,1,0) -> 0 | G117: =IF(OR(C117>0,D117>0),"1","") | H117: =IF(OR(C117=1,D117=1),1,0) -> 0
A118: Fiscalização de Pátio de Aeródromo | F118: =IF(B118>0,1,0) -> 0 | G118: =IF(OR(C118>0,D118>0),"1","") | H118: =IF(OR(C118=1,D118=1),1,0) -> 0
A119: Fogo de Conselho | F119: =IF(B119>0,1,0) -> 0 | G119: =IF(OR(C119>0,D119>0),"1","") | H119: =IF(OR(C119=1,D119=1),1,0) -> 0
A120: Fotografia | F120: =IF(B120>0,1,0) -> 0 | G120: =IF(OR(C120>0,D120>0),"1","") | H120: =IF(OR(C120=1,D120=1),1,0) -> 0
A121: Fotografia Digital | F121: =IF(B121>0,1,0) -> 0 | G121: =IF(OR(C121>0,D121>0),"1","") | H121: =IF(OR(C121=1,D121=1),1,0) -> 0
A122: Futebol | F122: =IF(B122>0,1,0) -> 0 | G122: =IF(OR(C122>0,D122>0),"1","") | H122: =IF(OR(C122=1,D122=1),1,0) -> 0
A123: Futebol de Mesa | F123: =IF(B123>0,1,0) -> 0 | G123: =IF(OR(C123>0,D123>0),"1","") | H123: =IF(OR(C123=1,D123=1),1,0) -> 0
A124: Gamão | F124: =IF(B124>0,1,0) -> 0 | G124: =IF(OR(C124>0,D124>0),"1","") | H124: =IF(OR(C124=1,D124=1),1,0) -> 0
A125: Garçom | F125: =IF(B125>0,1,0) -> 0 | G125: =IF(OR(C125>0,D125>0),"1","") | H125: =IF(OR(C125=1,D125=1),1,0) -> 0
A126: Genealogia | F126: =IF(B126>0,1,0) -> 0 | G126: =IF(OR(C126>0,D126>0),"1","") | H126: =IF(OR(C126=1,D126=1),1,0) -> 0
A127: Gênero Musical (antigo Rock) | F127: =IF(B127>0,1,0) -> 0 | G127: =IF(OR(C127>0,D127>0),"1","") | H127: =IF(OR(C127=1,D127=1),1,0) -> 0
... A154: Informática | F154: =IF(B154>0,1,0) -> 0 | G154: =IF(OR(C154>0,D154>0),"1","") | H154: =IF(OR(C154=1,D154=1),1,0) -> 0
A155: Insígnia Campeões da Natureza | F155: =IF(B155>0,1,0) -> 0
A156: Insígnia da Ação Comunitária | F156: =IF(B156>0,1,0) -> 0
A157: Insígnia da Lusofonia | F157: =IF(B157>0,1,0) -> 0
A158: Insígnia da Modalidade do Ar - Aviador | F158: =IF(B158>0,1,0) -> 0
A159: Insígnia da Modalidade do Mar - Grumete | F159: =IF(B159>0,1,0) -> 0
A160: Insígnia do Aprender | F160: =IF(B160>0,1,0) -> 0
A161: Insígnia do Cone Sul | F161: =IF(B161>0,1,0) -> 0
A162: Insígnia Escoteiros pela Energia Solar | F162: =IF(B162>0,1,0) -> 0
A163: Reduzir, Reciclar Reutilizar | F163: =IF(B163>0,1,0) -> 0
...

Sheet Habilidades para a Vida
C1: HABILIDADES PARA A VIDA
C3: APRENDIZAGEM CONTINUA E DESENVOLVIMENTO VOCACIONAL | H3: Soma blocos concluídos | I3: =I7+I78+I117+I164 -> 0
C4: Atividades do Programa Anterior que podem complementar as atividades variáveis:
C5: Atividades Pistas e Trilha Intelectual: I22, I23, I24, I25, I26, I32, I33 Atividades Rumo e Travessia Intelectual: I21, I22, I23, I24
C7: Intencionalidade Educativa | H7: BLOCO CONCLUÍDO ? | I7: =IF(B8="Bloco concluído",1,0) -> 0
B8: =IF(AND(A11="Atingiu 100% das ações fixas",A16="Atingiu 100% das ações variáveis"),"BLOCO CONCLUÍDO","") | C8: Explorar temas que despertam seu interesse, buscar informações confiáveis para aprender mais e experimentar novas ideias e recursos, aplicando esse conhecimento em atividades e projetos de serviço.
C10: Ações Educativas Fixas
A11: =IF(J13>=2,"Atingiu 100% das ações fixas","") | B11: =IF(J11>0,"Item OK","") | C11: Conquistar, no Ramo Escoteiro, uma especialidade sobre um tema de seu interesse e que seja um conhecimento novo. | D11: Alterar manualmente | E11: 0 | H11: Qualquer especialidade | I11: ='Especialidades ou Insígnias'!H313 -> 0 | J11: =IF(E11+I11>=1,1,0) -> 0
B12: =IF(J12>0,"Item OK","") | C12: Em conjunto com a sua patrulha, realizar um Percurso de Gilwell de pelo menos 3km. | D12: Alterar manualmente | F12: Pista 21 | G12: ='Pistas e Trilha'!A41 -> 0 | H12: Pista 22 | I12: ='Pistas e Trilha'!A42 -> 0 | J12: =IF(G12+I12>=2,1,0)+E12 -> 0
I13: soma | J13: =SUM(J11:J12) -> 0
C14: Ações Educativas Variáveis
C15: Realizar QUATRO ações dentre as listadas a seguir:
A16: =IF(OR(J71>0,J66>=4),"Atingiu 100% das ações variáveis","") | B16: =IF(J18>0,"Item OK","") | C16: Enviar e receber mensagens simples em Alfabeto Fonético,Código Internacional de Sinais, Semáfora, Heliografia, Cifra de César ou Criptografia. | D16: Alterar manualmente | F16: Pista 37 | G16: ='Pistas e Trilha'!A67 -> 0 | H16: Rumo 42 | I16: ='Rumo e Travessia'!A70 -> 0
F17: Esp. Entrega de Mensagens | G17: ='Especialidades ou Insígnias'!H102 -> 0
I18: soma | J18: =IF(G16+G17+I16+I17>=1,1,0)+E16 -> 0
B19: =IF(J19>0,"Item OK","") | C19: Visitar com a sua patrulha: hospital, quartel de bombeiros, delegacia, empresas, comércios locais ou outros para conhecer o funcionamento de diferentes profissões | D19: Alterar manualmente | F19: Pista 82 e 83 (ver Guia Aventura Escoteira, pág. 204) | G19: ='Pistas e Trilha'!A146 -> 0 | J19: =IF(G19+I19>=1,1,0)+E19 -> 0
B20: =IF(J22>0,"Item OK","") | C20: Conhecer o funcionamento de serviços de internet, rádio e TV e usar esses conhecimentos para resolver problemas técnicos. | D20: Alterar manualmente | F20: Esp Internet | G20: ='Especialidades ou Insígnias'!H164 -> 0 | H20: Rumo 41 | I20: ='Rumo e Travessia'!A69 -> 0 | J20: =IF(G20+I20>=1,1,0) -> 0
F21: Esp Radioamadorismo | G21: ='Especialidades ou Insígnias'!H253 -> 0 | J21: =IF(G21+I21>=1,1,0) -> 0
I22: soma | J22: =IF(G20+G21+I20+I21>=1,1,0)+E20 -> 0
B23: =IF(J25>0,"Item OK","") | C23: Convidar um especialista da comunidade para dialogar com a tropa e esclarecer dúvidas sobre determinado tema ou profissão | D23: Alterar manualmente | F23: Pista 70 | G23: ='Pistas e Trilha'!A124 -> 0 | H23: Rumo 21 a 24 | I23: ='Rumo e Travessia'!A38 -> 0 | J23: =IF(G23+I23>=1,1,0)+E23 -> 0
F24: Pista 33 | G24: ='Pistas e Trilha'!A59 -> 0
I25: soma | J25: =IF(G23+G24+I23>=1,1,0)+E23 -> 0
B26: =IF(J26>0,"Item OK","") | C26: Utilizar corretamente um radiocomunicador em atividade da patrulha | D26: Alterar manualmente | F26: Pista 38 | G26: ='Pistas e Trilha'!A68 -> 0 | J26: =IF(G26+I26>=1,1,0)+E26 -> 0
B27: =IF(J27>0,"Item OK","") | C27: Realizar uma pesquisa sobre um tema escolhido e apresentar os resultados para a patrulha ou tropa em formato criativo (cartaz, teatro, vídeo, oficina) | D27: Alterar manualmente | F27: Pista 61 | G27: ='Pistas e Trilha'!A109 -> 0 | H27: Rumo 27 | I27: ='Rumo e Travessia'!A47 -> 0 | J27: =IF(G27+I27>=1,1,0)+E27 -> 0
B28: =IF(J28>0,"Item OK","") | C28: Planejar e executar, em conjunto com a sua patrulha, uma ação de serviço comunitário baseada em informações pesquisadas sobre necessidades locais | D28: Alterar manualmente | H28: Rumo 91 | I28: ='Rumo e Travessia'!A154 -> 0 | J28: =IF(G28+I28>=1,1,0)+E28 -> 0
C29: Especialidades que podem complementar as Ações Educativas Variáveis
B30: =IF(J30>0,"Item OK","") | C30: Aeronáutica
B31: =IF(J31>0,"Item OK","") | C31: Arquitetura e Urbanismo | J31: ='Especialidades ou Insígnias'!H22 -> 0
B32: =IF(J32>0,"Item OK","") | C32: Astronomia | J32: ='Especialidades ou Insígnias'!H32 -> 0
B33: =IF(J33>0,"Item OK","") | C33: Biblioteconomia | J33: ='Especialidades ou Insígnias'!H38 -> 0
B34: =IF(J34>0,"Item OK","") | C34: Cartografia | J34: ='Especialidades ou Insígnias'!H50 -> 0
B35: =IF(J35>0,"Item OK","") | C35: Comunicações | J35: ='Especialidades ou Insígnias'!H62 -> 0
B36: =IF(J36>0,"Item OK","") | C36: Confeitaria | J36: ='Especialidades ou Insígnias'!H63 -> 0
B37: =IF(J37>0,"Item OK","") | C37: Construção Civil | J37: ='Especialidades ou Insígnias'!H64 -> 0
B38: =IF(J38>0,"Item OK","") | C38: Criptografia | J38: ='Especialidades ou Insígnias'!H71 -> 0
B39: =IF(J39>0,"Item OK","") | C39: Culinária | J39: ='Especialidades ou Insígnias'!H75 -> 0
B40: =IF(J40>0,"Item OK","") | C40: Design de Interiores | J40: ='Especialidades ou Insígnias'!H85 -> 0
B41: =IF(J41>0,"Item OK","") | C41: E-Sports | J41: ='Especialidades ou Insígnias'!H108 -> 0
B42: =IF(J42>0,"Item OK","") | C42: Etiqueta | J42: ='Especialidades ou Insígnias'!H112 -> 0
B43: =IF(J43>0,"Item OK","") | C43: Fiscalização de Pátio de Aeródromo | J43: ='Especialidades ou Insígnias'!H118 -> 0
...

Sheet Meio Ambiente
C1: MEIO AMBIENTE
C3: CONSUMO RESPONSÁVEL | H3: Soma blocos concluídos | I3: =I7+I45+I71+I111 -> 0
C4: Atividades do Programa Anterior que podem complementar as atividades variáveis:
C5: Atividades Rumo e Travessia Intelectual: I39, I40
C7: Intencionalidade Educativa | H7: BLOCO CONCLUÍDO ? | I7: =IF(B8="Bloco concluído",1,0) -> 0
B8: =IF(AND(A11="Atingiu 100% das ações fixas",A17="Atingiu 100% das ações variáveis"),"BLOCO CONCLUÍDO","") | C8: Praticar o consumo consciente diariamente, evitando desperdícios e ajudando a preservar os recursos naturais
C10: Ações Educativas Fixas
A11: =IF(J13>=2,"Atingiu 100% das ações fixas","") | B11: =IF(J11>0,"Item OK","") | C11: Em acampamentos e excursões, criar soluções para melhorar a higiene e conforto e classificar os resíduos em categorias, tratando-os adequadamente. | D11: Alterar manualmente | F11: pista 8 | G11: ='Pistas e Trilha'!A19 -> 0 | J11: =IF(G11+I11>=1,1,0)+E11 -> 0
B12: =IF(J12>0,"Item OK","") | C12: Planejar adequadamente e adquirir as quantidades dos alimentos para refeições em um acampamento para sua patrulha, evitando desperdício. | D12: Alterar manualmente | H12: rumo 13 | I12: ='Rumo e Travessia'!A24 -> 0 | J12: =IF(G12+I12>=1,1,0)+E12 -> 0
I13: soma | J13: =SUM(J11:J12) -> 0
C15: Ações Educativas Variáveis
C16: Realizar CINCO ações dentre as listadas a seguir:
A17: =IF(OR(H39>0,H35>=5),"Atingiu 100% das ações variáveis","") | B17: =IF(J17>0,"Item OK","") | C17: Registrar e analisar o consumo de água e energia da sua residência, buscando ideias para economizar, e apresentar para sua patrulha os resultados. | D17: Alterar manualmente | F17: Esp Energia n3 | G17: ='Especialidades ou Insígnias'!H98 -> 0 | J17: =IF(G17+I17>=1,1,0)+E17 -> 0
B18: =IF(J18>0,"Item OK","") | C18: Avaliar o impacto ambiental de uma atividade e apresentar alternativas mais sustentáveis. | D18: Alterar manualmente | F18: pista 1 | G18: ='Pistas e Trilha'!A8 -> 0 | H18: rumo 1 | I18: ='Rumo e Travessia'!A6 -> 0 | J18: =IF(G18+I18>=1,1,0)+E18 -> 0
B19: =IF(J19>0,"Item OK","") | C19: Visitar uma estação de energia renovável, uma estação de tratamento de água, uma cooperativa ou usina de reciclagem ou outras opções semelhantes. | D19: Alterar manualmente | F19: Esp Energia n3 | G19: ='Especialidades ou Insígnias'!H98 -> 0 | J19: =IF(G19+I19>=1,1,0)+E19 -> 0
B20: =IF(J20>0,"Item OK","") | C20: Consertar objetos simples, como brinquedos ou pequenos eletrodomésticos. | D20: Alterar manualmente | F20: Esp Reparos Domésticos n3 | G20: ='Especialidades ou Insígnias'!H260 -> 0 | J20: =IF(G20+I20>=1,1,0)+E20 -> 0
B21: =IF(J21>0,"Item OK","") | C21: Utilizar embalagens retornáveis ou reutilizáveis nas refeições de campo, evitando descartáveis. | D21: Alterar manualmente | F21: Pista 94 | G21: ='Pistas e Trilha'!A167 -> 0 | H21: rumo 1 | I21: ='Rumo e Travessia'!A6 -> 0 | J21: =IF(G21+I21>=1,1,0)+E21 -> 0
F22: Pista 1 | G22: ='Pistas e Trilha'!A8 -> 0
I23: soma | J23: =IF(G21+G22+I21+I22>=2,1,0)+E21 -> 0
B24: =IF(J24>0,"Item OK","") | C24: Separar resíduos orgânicos e criar um sistema de compostagem caseira | D24: Alterar manualmente | F24: Esp Compostagem | G24: ='Especialidades ou Insígnias'!H61 -> 0 | J24: =IF(G24+I24>=1,1,0)+E24 -> 0
B25: =IF(J25>0,"Item OK","") | C25: Criar uma campanha educativa para a tropa sobre consumo consciente e economia de recursos. | D25: Alterar manualmente | J25: =IF(G25+I25>=1,1,0)+E25 -> 0
B26: =IF(J26>0,"Item OK","") | C26: Trocar roupas, livros ou jogos com amigos e familiares em vez de comprar novos. | D26: Alterar manualmente | J26: =IF(G26+I26>=1,1,0)+E26 -> 0
B27: =IF(J27>0,"Item OK","") | C27: Organizar, com sua patrulha, uma campanha de conscientização sobre consumo responsável. | D27: Alterar manualmente | J27: =IF(G27+I27>=1,1,0)+E27 -> 0
B28: =IF(J28>0,"Item OK","") | C28: Confeccionar utensílios ou equipamentos a partir de materiais reciclados para uso nas atividades da patrulha. | D28: Alterar manualmente | J28: =IF(G28+I28>=1,1,0)+E28 -> 0
B29: =IF(J29>0,"Item OK","") | C29: Planejar e realizar as refeições de um dia de acampamento sem carne, garantindo a ingestão adequada de proteínas. | D29: Alterar manualmente | J29: =IF(G29+I29>=1,1,0)+E29 -> 0
B30: =IF(J30>0,"Item OK","") | C30: Organizar, cuidar e fazer reparos nos materiais da patrulha. | D30: Alterar manualmente | J30: =IF(G30+I30>=1,1,0)+E30 -> 0
C31: Especialidades que podem complementar as Ações Educativas Variáveis
B32: =IF(H32>0,"Item OK","") | C32: Agricultura | H32: ='Especialidades ou Insígnias'!H11 -> 0
B33: =IF(H33>0,"Item OK","") | C33: Aquicultura | H33: ='Especialidades ou Insígnias'!H19 -> 0
B34: =IF(H34>0,"Item OK","") | C34: Energia | H34: ='Especialidades ou Insígnias'!H98 -> 0
G35: soma | H35: =SUM(J17:J30)-J21-J22+H32+H33+H34 -> 0
C36: Conquistar ao menos uma das seguintes especialidades a seguir no nível 2 ou Insígnias
B37: =IF(H37>0,"Item OK","") | C37: Horticultura | H37: ='Especialidades ou Insígnias'!H149 -> 0
B38: =IF(H38>0,"Item OK","") | C38: Reduzir, Reciclar e Reutilizar | H38: ='Especialidades ou Insígnias'!B163 -> 0
G39: soma | H39: =SUM(H37:H38) -> 0
C41: MUDANÇAS CLIMÁTICAS
C42: Atividades do Programa Anterior que podem complementar as atividades variáveis:
C43: Atividades Pistas e Trilha Intelectual: I27 Atividades Rumo e Travessia Social: S100, S101, S102
C45: Intencionalidade Educativa | H45: BLOCO CONCLUÍDO ? | I45: =IF(B46="Bloco concluído",1,0) -> 0
B46: =IF(A50="Atingiu 100% das ações variáveis","BLOCO CONCLUÍDO","") | C46: Se envolver em atividades e projetos para reduzir os impactos ambientais e combater as mudanças climáticas.
...

Sheet Paz e Desenvolvimento
C1: PAZ E DESENVOLVIMENTO
C3: COMUNIDADE | F3: Soma blocos concluídos | G3: =G7+G33+G57+G111+G147 -> 0
C4: Atividades do Programa Anterior que podem complementar as atividades variáveis:
C5: Atividades Pistas e Trilha Social: S80, S81 Atividades Rumo e Travessia Intelectual: I33, I34, I35 Social: S88, S89, S90, S91
C7: Intencionalidade Educativa | F7: BLOCO CONCLUÍDO ? | G7: =IF(B8="Bloco concluído",1,0) -> 0
B8: =IF(AND(A11="Atingiu 100% das ações fixas",A16="Atingiu 100% das ações variáveis"),"BLOCO CONCLUÍDO","") | C8: Realizar boas ações diariamente e trabalhar em equipe para organizar atividades e projetos de serviço que beneficiem a comunidade
C10: Ações Educativas Fixas
A11: =IF(J13>=2,"Atingiu 100% das ações fixas","") | B11: =IF(J11>0,"Item OK","") | C11: Identificar, sozinho ou em patrulha, uma necessidade da comunidade e planejar e executar uma ação comunitária. | D11: Alterar manualmente | H11: rumo 91 | I11: ='Rumo e Travessia'!A154 -> 0 | J11: =IF(G11+I11>=1,1,0)+E11 -> 0
B12: =IF(J12>0,"Item OK","") | C12: Identificar os riscos de desastres naturais na comunidade e conhecer os hospitais e contatos de emergência, sabendo quando acionar cada um. | D12: Alterar manualmente | H12: rumo 4 a 7 | I12: ='Rumo e Travessia'!A10 -> 0 | J12: =IF(G12+I12>=1,1,0)+E12 -> 0
I13: soma | J13: =SUM(J11:J12) -> 0
C14: Ações Educativas Variáveis
C15: Realizar TRÊS ações dentre as listadas a seguir:
A16: =IF(OR(J27>0,J23>=3),"Atingiu 100% das ações variáveis","") | B16: =IF(J16>0,"Item OK","") | C16: Aplicar o conhecimento adquirido nas especialidades em ações de serviço à comunidade. | D16: Alterar manualmente | H16: rumo 33 | I16: ='Rumo e Travessia'!A52 -> 0 | J16: =IF(G16+I16>=1,1,0)+E16 -> 0
B17: =IF(J17>0,"Item OK","") | C17: Participar ativamente de pelo menos uma campanha de serviço e desenvolvimento comunitário organizadas pela UEL, distrito ou região. | D17: Alterar manualmente | F17: pista 80 e 81 | G17: ='Pistas e Trilha'!A142 -> 0 | H17: rumo 70 | I17: ='Rumo e Travessia'!A118 -> 0 | J17: =IF(G17+I17>=1,1,0)+E17 -> 0
B18: =IF(J18>0,"Item OK","") | C18: Organizar uma oficina de brinquedos, doando os itens consertados para uma instituição que atende crianças carentes. | D18: Alterar manualmente | H18: rumo 60 | I18: ='Rumo e Travessia'!A101 -> 0 | J18: =IF(G18+I18>=1,1,0)+E18 -> 0
B19: =IF(J19>0,"Item OK","") | C19: Colaborar em ações organizadas por outras instituições de serviço. | D19: Alterar manualmente | F19: pista 80 e 81 | G19: ='Pistas e Trilha'!A152 -> 0 | H19: rumo 70 | I19: ='Rumo e Travessia'!A118 -> 0 | J19: =IF(G19+I19>=1,1,0)+E19 -> 0
C20: Especialidades que podem complementar as Ações Educativas Variáveis
B21: =IF(J21>0,"Item OK","") | C21: Inclusão | J21: ='Especialidades ou Insígnias'!H152 -> 0
B22: =IF(J22>0,"Item OK","") | C22: Libras | J22: ='Especialidades ou Insígnias'!H176 -> 0
C23: OU conquistar ao menos uma das seguintes especialidades a seguir no nível 2 ou Insígnias | I23: soma | J23: =SUM(J16:J22) -> 0
B24: =IF(J24>0,"Item OK","") | C24: Defesa Civil | J24: ='Especialidades ou Insígnias'!H83 -> 0
B25: =IF(J25>0,"Item OK","") | C25: Mensageiros da Paz | J25: ='Especialidades ou Insígnias'!H195 -> 0
B26: =IF(J26>0,"Item OK","") | C26: Insíginia da Ação Comunitária | J26: ='Especialidades ou Insígnias'!B156 -> 0
I27: soma | J27: =SUM(J24:J26) -> 0
C29: DEMOCRACIA
C30: Atividades do Programa Anterior que podem complementar as atividades variáveis:
C31: Atividades Pistas e Trilha Afetivo A59, A60, A61, A62 Social: S77, S78, S79 Atividades Rumo e Travessia Social: S81, S82, S83, S84, S85, S86, S87
C33: Intencionalidade Educativa | F33: BLOCO CONCLUÍDO ? | G33: =IF(B34="Bloco concluído",1,0) -> 0
B34: =IF(AND(A37="Atingiu 100% das ações fixas",A43="Atingiu 100% das ações variáveis"),"BLOCO CONCLUÍDO","") | C34: Participar das decisões da tropa, contribuindo com suas ideias, respeitando as opiniões dos colegas e se comprometendo a seguir o que foi decidido coletivamente.
C36: Ações Educativas Fixas
A37: =IF(J40>=3,"Atingiu 100% das ações fixas","") | B37: =IF(J37>0,"Item OK","") | C37: Participar ativamente das decisões do Conselho de Patrulha, contribuindo com ideias, votando e assumindo responsabilidades, respeitando os resultados | D37: Alterar manualmente | H37: rumo 67 | I37: ='Rumo e Travessia'!A113 -> 0 | J37: =IF(G37+I37>=1,1,0)+E37 -> 0
B38: =IF(J38>0,"Item OK","") | C38: Participar ativamente das decisões da Assembleia de Tropa, contribuindo com ideias, votando e assumindo responsabilidades, respeitando os resultados | D38: Alterar manualmente | F38: pista 59 a 62 | G38: ='Pistas e Trilha'!A106 -> 0 | J38: =IF(G38+I38>=1,1,0)+E38 -> 0
B39: =IF(J39>0,"Item OK","") | C39: Participar da eleição de monitor da patrulha e das decisões de encargos, respeitando os resultados | D39: Alterar manualmente | F39: pista 52 a 54 | G39: ='Pistas e Trilha'!A94 -> 0 | J39: =IF(G39+I39>=1,1,0)+E39 -> 0
I40: soma | J40: =SUM(J37:J39) -> 0
C41: Ações Educativas Variáveis
C42: Realizar DUAS ações dentre as listadas a seguir:
A43: =IF(J51>=2,"Atingiu 100% das ações variáveis","") | B43: =IF(J43>0,"Item OK","") | C43: Visitar a sede administrativa de qualquer um dos três poderes, e explicar a importância e as particularidades desta forma de governo, conhecendo a constituição e os símbolos nacionais, do estado e município. | D43: Alterar manualmente | H43: rumo 82 | I43: ='Rumo e Travessia'!A139 -> 0 | J43: =IF(G43+I43>=1,1,0)+E43 -> 0
B44: =IF(J44>0,"Item OK","") | C44: Conhecer a estrutura do Grupo Escoteiro ou Seção Autônoma e participar de uma Assembleia de Grupo Escoteiro. | D44: Alterar manualmente | F44: pista 79 | G44: ='Pistas e Trilha'!A140 -> 0 | H44: rumo 84 | I44: ='Rumo e Travessia'!A143 -> 0 | J44: =IF(G44+I44>=1,1,0)+E44 -> 0
B45: =IF(J45>0,"Item OK","") | C45: Participar ativamente de um fórum de jovens do grupo escoteiro. | D45: Alterar manualmente | J45: =IF(G45+I45>=1,1,0)+E45 -> 0
B46: =IF(J46>0,"Item OK","") | C46: Aprender e compartilhar sobre a história do voto e da democracia no Brasil. | D46: Alterar manualmente | H46: rumo 81 a 83 | I46: ='Rumo e Travessia'!A137 -> 0 | J46: =IF(G46+I46>=1,1,0)+E46 -> 0
...

Sheet Saúde e Bem Estar
C1: SAÚDE E BEM ESTAR
C3: CUIDADO COM O CORPO | F3: Soma blocos concluídos | G3: =G7+G45+G68+G127+G169 -> 0
C4: Atividades do Programa Anterior que podem complementar as atividades variáveis:
C5: Atividades Pistas e Trilha Físico: F4, F5, F6, F7 Social: S82, S83 Atividades Rumo e Travessia Físico: F1, F2, F3, F4, F5, F6, F7
C7: Intencionalidade Educativa | F7: BLOCO CONCLUÍDO ? | G7: =IF(B8="Bloco concluído",1,0) -> 0
B8: =IF(AND(A11="Atingiu 100% das ações fixas",A19="Atingiu 100% das ações variáveis"),"BLOCO CONCLUÍDO","") | C8: Compreender e respeitar as mudanças do seu próprio corpo e das outras pessoas, independentemente de aparência, identidade ou orientação sexual. Se desafiar a superar suas limitações físicas e aprender técnicas básicas de primeiros socorros.
C10: Ações Educativas Fixas
A11: =IF(J16>=3,"Atingiu 100% das ações fixas","") | B11: =IF(J11>0,"Item OK","") | C11: Conhecer as ações iniciais em acidentes e como cuidar de: - pequenos cortes; - contusões; - escoriações; - queimaduras e - picadas de animais peçonhentos. | D11: Alterar manualmente | H11: Especialidade 1º socorros, n3 | I11: ='Especialidades ou Insígnias'!H243 -> 0 | J11: =IF(G11+I11>=1,1,0)+E11 -> 0
B12: =IF(J14>0,"Item OK","") | C12: Aplicar técnicas de bandagens e transporte de feridos. | D12: Alterar manualmente | F12: Pistas 5 | G12: ='Pistas e Trilha'!A14 -> 0 | H12: Rumo 4 a 7 | I12: ='Rumo e Travessia'!A10 -> 0 | J12: =IF(G12+I12>=1,1,0) -> 0
H13: Especialidade 1º socorros, n3 | I13: ='Especialidades ou Insígnias'!H243 -> 0 | J13: =IF(G13+I13>=1,1,0) -> 0
I14: soma | J14: =IF(G12+I12+G14>=2,1,0)+E12 -> 0
B15: =IF(J15>0,"Item OK","") | C15: Cuidar da segurança física e mental nas atividades escoteiras, respeitando os limites próprios e dos outros, e seguindo as orientações dos escotistas. | D15: Alterar manualmente | F15: Pistas 6 | G15: ='Pistas e Trilha'!A15 -> 0 | H15: Rumo 1 a 3 | I15: ='Rumo e Travessia'!A5 -> 0 | J15: =IF(G15+I15>=1,1,0)+E15 -> 0
I16: soma | J16: =J11+J14+J15 -> 0
C17: Ações Educativas Variáveis
C18: Realizar QUATRO ações dentre as listadas a seguir:
A19: =IF(OR(J39>0,J35>=4),"Atingiu 100% das ações variáveis","") | B19: =IF(J19>0,"Item OK","") | C19: Conhecer as medidas do seu corpo (palmo, envergadura, passo simples e duplo) e aplicá-las durante uma excursão com sua patrulha | D19: Alterar manualmente | F19: pistas 3 | G19: ='Pistas e Trilha'!A10 -> 0 | J19: =IF(G19+I19>=1,1,0)+E19 -> 0
B20: =IF(J20>0,"Item OK","") | C20: Participar de uma atividade, oficina, palestra que trate dos malefícios dos seguintes assuntos: anorexia, bulimia, drogas, álcool, cigarro e cigarros eletrônicos. | D20: Alterar manualmente | F20: Pistas 55 | G20: ='Pistas e Trilha'!A101 -> 0 | H20: Rumo 2 | I20: ='Rumo e Travessia'!A7 -> 0 | J20: =IF(G20+I20>=1,1,0)+E20 -> 0
B21: =IF(J21>0,"Item OK","") | C21: Saber contato dos órgãos de emergência e saber como informar os sinais vitais e situação da vítima. | D21: Alterar manualmente | F21: Especialidade 1º socorros, n3 | G21: ='Especialidades ou Insígnias'!H243 -> 0 | J21: =IF(G21+I21>=1,1,0)+E21 -> 0
B22: =IF(J22>0,"Item OK","") | C22: Participar de uma simulação de acidente e atuar em conjunto com a sua patrulha. | D22: Alterar manualmente | F22: Especialidade salvamento, n3 | G22: ='Especialidades ou Insígnias'!H265 -> 0 | H22: rumo 6 | I22: ='Rumo e Travessia'!A13 -> 0 | J22: =IF(G22+I22>=1,1,0)+E22 -> 0
B23: =IF(J23>0,"Item OK","") | C23: Proteger-se do sol e do frio durante as atividades, identificando casos de desidratação e insolação, e respeitar os limites do seu corpo. | D23: Alterar manualmente | F23: Pistas 7 | G23: ='Pistas e Trilha'!A16 -> 0 | J23: =IF(G23+I23>=1,1,0)+E23 -> 0
B24: =IF(J24>0,"Item OK","") | C24: Demonstrar como ajudar uma pessoa em casos de obstrução das vias aéreas e convulsões | D24: Alterar manualmente | F24: Especialidade 1º socorros, n3 | G24: ='Especialidades ou Insígnias'!H243 -> 0 | J24: =IF(G24+I24>=1,1,0)+E24 -> 0
B25: =IF(J25>0,"Item OK","") | C25: Conhecer os itens que compõem a caixa de primeiros socorros da patrulha e mantê-la organizada. | D25: Alterar manualmente | F25: pistas 4 | G25: ='Pistas e Trilha'!A13 -> 0 | J25: =IF(G25+I25>=1,1,0)+E25 -> 0
B26: =IF(J26>0,"Item OK","") | C26: Saber agir em casos de hemorragia. | D26: Alterar manualmente | F26: Especialidade 1º socorros, n3 | G26: ='Especialidades ou Insígnias'!H243 -> 0 | H26: Rumo 7 | I26: ='Rumo e Travessia'!A14 -> 0 | J26: =IF(G26+I26>=1,1,0)+E26 -> 0
C27: Especialidades que podem complementar as Ações Educativas Variáveis
B28: =IF(J28>0,"Item OK","") | C28: Babá | J28: ='Especialidades ou Insígnias'!H34 -> 0
B29: =IF(J29>0,"Item OK","") | C29: Cuidados com Idosos | J29: ='Especialidades ou Insígnias'!H74 -> 0
C30: Maquiagem | J30: ='Especialidades ou Insígnias'!H187 -> 0
B31: =IF(J31>0,"Item OK","") | C31: Vigilância Epidemiológica | J31: ='Especialidades ou Insígnias'!H305 -> 0
B32: =IF(J32>0,"Item OK","") | C32: Salvamento | J32: ='Especialidades ou Insígnias'!H265 -> 0
C33: Segurança e Emergência Náutica | J33: ='Especialidades ou Insígnias'!H271 -> 0
B34: =IF(J34>0,"Item OK","") | C34: Segurança | J34: ='Especialidades ou Insígnias'!H268 -> 0
C35: OU conquistar ao menos uma das seguintes especialidades a seguir no nível 2 | I35: soma | J35: =SUM(J19:J34) -> 0
B36: =IF(J36>0,"Item OK","") | C36: Anatomia Humana | J36: ='Especialidades ou Insígnias'!H14 -> 0
B37: =IF(J37>0,"Item OK","") | C37: Prevenção em Saúde | J37: ='Especialidades ou Insígnias'!H242 -> 0
B38: =IF(J38>0,"Item OK","") | C38: Primeiros Socorros | J38: ='Especialidades ou Insígnias'!H243 -> 0
I39: soma | J39: =SUM(J36:J38) -> 0
C41: ESPIRITUALIDADE
C42: Atividades do Programa Anterior que podem complementar as atividades variáveis:
C43: Atividades Pistas e Trilha Espiritual: E97, E98, E99, E103, E104, E105, E106 Atividades Rumo e Travessia Espiritual: E103, E104, E105, E106, E107, E108
C45: Intencionalidade Educativa | F45: BLOCO CONCLUÍDO ? | G45: =IF(B46="Bloco concluído",1,0) -> 0
...
