Workbook

Sheet Análise Geral
I1: Habilidades para a Vida | P1: Meio Ambiente | W1: Paz e Desenvolvimento | AE1: Saúde e Bem-Estar
A2: Escoteiro | B2: Ch. Progr. | C2: Patrulha | D2: Progr. | E2: Dt. Nasc. | F2: idade (ano) | G2: Idade | H2: Ações Faltantes | I2: Aprend. Cont. Desenv. Vocacional | J2: Autonomia e Liderança | K2: Criatividade e Inovação | L2: Inteligência Emocional | M2: Ações Realiz. | N2: Tot. Ações | O2: Média | P2: Consumo Responsável | Q2: Mudanças Climáticas | R2: Preservação da Biodiversidade | S2: Vida ao Ar Livre | T2: Ações Realiz. | U2: Tot. Ações | V2: Média | W2: Comunidade | X2: Democracia | Y2: Herança Cultural | Z2: Promoção da Paz | AA2: Valores | AB2: Ações Realiz. | AC2: Tot. Ações | AD2: Média | AE2: Cuidado com o Corpo | AF2: Espiritualidade | AG2: Hábitos Saudáveis | AH2: Saúde Mental | AI2: Vínculos Saudáveis | AJ2: Ações Realiz. | AK2: Tot. Ações | AL2: Média | AM2: Ações Realiz. | AN2: Média GERAL | AO2: Ações Ideias | AP2: % tmp ano
A3: ='Escoteiro 1'!C1 -> Escoteiro 1 | B3: Chefe 1 | C3: Patrulha 1 | D3: Caminho | E3: 42005 | F3: =DATEDIF(E3,TODAY(),"M")/12 -> 11.083333 | G3: =datedif(E3,today(),"Y")&" a "&datedif(E3,today(),"YM")&" m" -> 11 a 1 m | H3: =AO3-AM3 -> 1.7083333 | I3: =INDIRECT("'"&A3&"'!$L$4") -> 0 | J3: =INDIRECT("'"&A3&"'!$L$5") -> 0 | K3: =INDIRECT("'"&A3&"'!$L$6") -> 0 | L3: =INDIRECT("'"&A3&"'!$L$7") -> 0 | M3: =sum(INDIRECT("'"&A3&"'!$K$4:$K$7")) -> 0 | N3: =sum(INDIRECT("'"&A3&"'!$G$4:$G$7")) -> 23 | O3: =average(I3:L3) -> 0 | P3: =INDIRECT("'"&A3&"'!$L$8") -> 0 | Q3: =INDIRECT("'"&A3&"'!$L$9") -> 0 | R3: =INDIRECT("'"&A3&"'!$L$10") -> 0 | S3: =INDIRECT("'"&A3&"'!$L$11") -> 0 | T3: =sum(INDIRECT("'"&A3&"'!$K$8:$K$11")) -> 0 | U3: =sum(INDIRECT("'"&A3&"'!$G$8:$G$11")) -> 29 | V3: =average(P3:S3) -> 0 | W3: =INDIRECT("'"&A3&"'!$L$12") -> 0 | X3: =INDIRECT("'"&A3&"'!$L$13") -> 0 | Y3: =INDIRECT("'"&A3&"'!$L$14") -> 0 | Z3: =INDIRECT("'"&A3&"'!$L$15") -> 0 | AA3: =INDIRECT("'"&A3&"'!$L$16") -> 0 | AB3: =sum(INDIRECT("'"&A3&"'!$K$12:$K$16")) -> 0 | AC3: =sum(INDIRECT("'"&A3&"'!$G$12:$G$16")) -> 28 | AD3: =average(W3:AA3) -> 0 | AE3: =INDIRECT("'"&A3&"'!$L$17") -> 0 | AF3: =INDIRECT("'"&A3&"'!$L$18") -> 0 | AG3: =INDIRECT("'"&A3&"'!$L$19") -> 0 | AH3: =INDIRECT("'"&A3&"'!$L$20") -> 0 | AI3: =INDIRECT("'"&A3&"'!$L$21") -> 0 | AJ3: =sum(INDIRECT("'"&A3&"'!$K$17:$K$21")) -> 0 | AK3: =sum(INDIRECT("'"&A3&"'!$G$17:$G$21")) -> 30 | AL3: =average(AE3:AI3) -> 0 | AM3: =M3+T3+AB3+AJ3 -> 0 | AN3: =AM3/(N3+U3+AC3+AK3) -> 0 | AO3: =(N3+U3+AB3+AK3)*AP3 -> 1.7083333 | AP3: =(F3-11)/4 -> 0.020833333
A4: ='Escoteiro 2'!C1 -> Escoteiro 2 | B4: Chefe 1 | C4: Patrulha 2 | D4: Caminho | E4: 42006 | F4: =DATEDIF(E4,TODAY(),"M")/12 -> 11.083333 | G4: =datedif(E4,today(),"Y")&" a "&datedif(E4,today(),"YM")&" m" -> 11 a 1 m | H4: =AO4-AM4 -> 1.7083333 | I4: =INDIRECT("'"&A4&"'!$L$4") -> 0 | J4: =INDIRECT("'"&A4&"'!$L$5") -> 0 | K4: =INDIRECT("'"&A4&"'!$L$6") -> 0 | L4: =INDIRECT("'"&A4&"'!$L$7") -> 0 | M4: =sum(INDIRECT("'"&A4&"'!$K$4:$K$7")) -> 0 | N4: =sum(INDIRECT("'"&A4&"'!$G$4:$G$7")) -> 23 | O4: =average(I4:L4) -> 0 | P4: =INDIRECT("'"&A4&"'!$L$8") -> 0 | Q4: =INDIRECT("'"&A4&"'!$L$9") -> 0 | R4: =INDIRECT("'"&A4&"'!$L$10") -> 0 | S4: =INDIRECT("'"&A4&"'!$L$11") -> 0 | T4: =sum(INDIRECT("'"&A4&"'!$K$8:$K$11")) -> 0 | U4: =sum(INDIRECT("'"&A4&"'!$G$8:$G$11")) -> 29 | V4: =average(P4:S4) -> 0 | W4: =INDIRECT("'"&A4&"'!$L$12") -> 0 | X4: =INDIRECT("'"&A4&"'!$L$13") -> 0 | Y4: =INDIRECT("'"&A4&"'!$L$14") -> 0 | Z4: =INDIRECT("'"&A4&"'!$L$15") -> 0 | AA4: =INDIRECT("'"&A4&"'!$L$16") -> 0 | AB4: =sum(INDIRECT("'"&A4&"'!$K$12:$K$16")) -> 0 | AC4: =sum(INDIRECT("'"&A4&"'!$G$12:$G$16")) -> 28 | AD4: =average(W4:AA4) -> 0 | AE4: =INDIRECT("'"&A4&"'!$L$17") -> 0 | AF4: =INDIRECT("'"&A4&"'!$L$18") -> 0 | AG4: =INDIRECT("'"&A4&"'!$L$19") -> 0 | AH4: =INDIRECT("'"&A4&"'!$L$20") -> 0 | AI4: =INDIRECT("'"&A4&"'!$L$21") -> 0 | AJ4: =sum(INDIRECT("'"&A4&"'!$K$17:$K$21")) -> 0 | AK4: =sum(INDIRECT("'"&A4&"'!$G$17:$G$21")) -> 30 | AL4: =average(AE4:AI4) -> 0 | AM4: =M4+T4+AB4+AJ4 -> 0 | AN4: =AM4/(N4+U4+AC4+AK4) -> 0 | AO4: =(N4+U4+AB4+AK4)*AP4 -> 1.7083333 | AP4: =(F4-11)/4 -> 0.020833333
A5: ='Escoteiro 3'!C1 -> Escoteiro 3 | B5: Chefe 1 | C5: Patrulha 3 | D5: Caminho | E5: 42007 | F5: =DATEDIF(E5,TODAY(),"M")/12 -> 11.083333 | G5: =datedif(E5,today(),"Y")&" a "&datedif(E5,today(),"YM")&" m" -> 11 a 1 m | H5: =AO5-AM5 -> 93.958333 | I5: =INDIRECT("'"&A5&"'!$L$4") -> 0 | J5: =INDIRECT("'"&A5&"'!$L$5") -> 0 | K5: =INDIRECT("'"&A5&"'!$L$6") -> 0 | L5: =INDIRECT("'"&A5&"'!$L$7") -> 0 | M5: =sum(INDIRECT("'"&A5&"'!$K$4:$K$7")) -> 0 | N5: =sum(INDIRECT("'"&A5&"'!$G$4:$G$7")) -> 23 | O5: =average(I5:L5) -> 0 | P5: =INDIRECT("'"&A5&"'!$L$8") -> 0 | Q5: =INDIRECT("'"&A5&"'!$L$9") -> 0 | R5: =INDIRECT("'"&A5&"'!$L$10") -> 0 | S5: =INDIRECT("'"&A5&"'!$L$11") -> 0 | T5: =sum(INDIRECT("'"&A5&"'!$K$8:$K$11")) -> 0 | U5: =sum(INDIRECT("'"&A5&"'!$G$8:$G$11")) -> 29 | V5: =average(P5:S5) -> 0 | W5: =INDIRECT("'"&A5&"'!$L$12") -> 0 | X5: =INDIRECT("'"&A5&"'!$L$13") -> 0 | Y5: =INDIRECT("'"&A5&"'!$L$14") -> 0 | Z5: =INDIRECT("'"&A5&"'!$L$15") -> 0 | AA5: =INDIRECT("'"&A5&"'!$L$16") -> 0 | AB5: =sum(INDIRECT("'"&A5&"'!$K$12:$K$16")) -> 0 | AC5: =sum(INDIRECT("'"&A5&"'!$G$12:$G$16")) -> 28 | AD5: =average(W5:AA5) -> 0 | AE5: =INDIRECT("'"&A5&"'!$L$17") -> 0 | AF5: =INDIRECT("'"&A5&"'!$L$18") -> 0 | AG5: =INDIRECT("'"&A5&"'!$L$19") -> 0 | AH5: =INDIRECT("'"&A5&"'!$L$20") -> 0 | AI5: =INDIRECT("'"&A5&"'!$L$21") -> 0 | AJ5: =sum(INDIRECT("'"&A5&"'!$K$17:$K$21")) -> 0 | AK5: =sum(INDIRECT("'"&A5&"'!$G$17:$G$21")) -> 30 | AL5: =average(AE5:AI5) -> 0 | AM5: =M5+T5+AB5+AJ5 -> 0 | AN5: =AM5/(N5+U5+AC5+AK5) -> 0 | AO5: =(N5+U5+AB5+AK5)*AP5 -> 93.958333 | AP5: =(F5-6.5)/4 -> 1.1458333
A6: ='Escoteiro 4'!C1 -> Escoteiro 4 | B6: Chefe 1 | C6: Patrulha 1 | D6: Pistas | E6: 42008 | F6: =DATEDIF(E6,TODAY(),"M")/12 -> 11.083333 | G6: =datedif(E6,today(),"Y")&" a "&datedif(E6,today(),"YM")&" m" -> 11 a 1 m | H6: =AO6-AM6 -> 93.958333 | I6: =INDIRECT("'"&A6&"'!$L$4") -> 0 | J6: =INDIRECT("'"&A6&"'!$L$5") -> 0 | K6: =INDIRECT("'"&A6&"'!$L$6") -> 0 | L6: =INDIRECT("'"&A6&"'!$L$7") -> 0 | M6: =sum(INDIRECT("'"&A6&"'!$K$4:$K$7")) -> 0 | N6: =sum(INDIRECT("'"&A6&"'!$G$4:$G$7")) -> 23 | O6: =average(I6:L6) -> 0 | P6: =INDIRECT("'"&A6&"'!$L$8") -> 0 | Q6: =INDIRECT("'"&A6&"'!$L$9") -> 0 | R6: =INDIRECT("'"&A6&"'!$L$10") -> 0 | S6: =INDIRECT("'"&A6&"'!$L$11") -> 0 | T6: =sum(INDIRECT("'"&A6&"'!$K$8:$K$11")) -> 0 | U6: =sum(INDIRECT("'"&A6&"'!$G$8:$G$11")) -> 29 | V6: =average(P6:S6) -> 0 | W6: =INDIRECT("'"&A6&"'!$L$12") -> 0 | X6: =INDIRECT("'"&A6&"'!$L$13") -> 0 | Y6: =INDIRECT("'"&A6&"'!$L$14") -> 0 | Z6: =INDIRECT("'"&A6&"'!$L$15") -> 0 | AA6: =INDIRECT("'"&A6&"'!$L$16") -> 0 | AB6: =sum(INDIRECT("'"&A6&"'!$K$12:$K$16")) -> 0 | AC6: =sum(INDIRECT("'"&A6&"'!$G$12:$G$16")) -> 28 | AD6: =average(W6:AA6) -> 0 | AE6: =INDIRECT("'"&A6&"'!$L$17") -> 0 | AF6: =INDIRECT("'"&A6&"'!$L$18") -> 0 | AG6: =INDIRECT("'"&A6&"'!$L$19") -> 0 | AH6: =INDIRECT("'"&A6&"'!$L$20") -> 0 | AI6: =INDIRECT("'"&A6&"'!$L$21") -> 0 | AJ6: =sum(INDIRECT("'"&A6&"'!$K$17:$K$21")) -> 0 | AK6: =sum(INDIRECT("'"&A6&"'!$G$17:$G$21")) -> 30 | AL6: =average(AE6:AI6) -> 0 | AM6: =M6+T6+AB6+AJ6 -> 0 | AN6: =AM6/(N6+U6+AC6+AK6) -> 0 | AO6: =(N6+U6+AB6+AK6)*AP6 -> 93.958333 | AP6: =(F6-6.5)/4 -> 1.1458333
A7: ='Escoteiro 5'!C1 -> Escoteiro 5 | B7: Chefe 1 | C7: Patrulha 2 | D7: Pistas | E7: 42009 | F7: =DATEDIF(E7,TODAY(),"M")/12 -> 11.083333 | G7: =datedif(E7,today(),"Y")&" a "&datedif(E7,today(),"YM")&" m" -> 11 a 1 m | H7: =AO7-AM7 -> 93.958333 | I7: =INDIRECT("'"&A7&"'!$L$4") -> 0 | J7: =INDIRECT("'"&A7&"'!$L$5") -> 0 | K7: =INDIRECT("'"&A7&"'!$L$6") -> 0 | L7: =INDIRECT("'"&A7&"'!$L$7") -> 0 | M7: =sum(INDIRECT("'"&A7&"'!$K$4:$K$7")) -> 0 | N7: =sum(INDIRECT("'"&A7&"'!$G$4:$G$7")) -> 23 | O7: =average(I7:L7) -> 0 | P7: =INDIRECT("'"&A7&"'!$L$8") -> 0 | Q7: =INDIRECT("'"&A7&"'!$L$9") -> 0 | R7: =INDIRECT("'"&A7&"'!$L$10") -> 0 | S7: =INDIRECT("'"&A7&"'!$L$11") -> 0 | T7: =sum(INDIRECT("'"&A7&"'!$K$8:$K$11")) -> 0 | U7: =sum(INDIRECT("'"&A7&"'!$G$8:$G$11")) -> 29 | V7: =average(P7:S7) -> 0 | W7: =INDIRECT("'"&A7&"'!$L$12") -> 0 | X7: =INDIRECT("'"&A7&"'!$L$13") -> 0 | Y7: =INDIRECT("'"&A7&"'!$L$14") -> 0 | Z7: =INDIRECT("'"&A7&"'!$L$15") -> 0 | AA7: =INDIRECT("'"&A7&"'!$L$16") -> 0 | AB7: =sum(INDIRECT("'"&A7&"'!$K$12:$K$16")) -> 0 | AC7: =sum(INDIRECT("'"&A7&"'!$G$12:$G$16")) -> 28 | AD7: =average(W7:AA7) -> 0 | AE7: =INDIRECT("'"&A7&"'!$L$17") -> 0 | AF7: =INDIRECT("'"&A7&"'!$L$18") -> 0 | AG7: =INDIRECT("'"&A7&"'!$L$19") -> 0 | AH7: =INDIRECT("'"&A7&"'!$L$20") -> 0 | AI7: =INDIRECT("'"&A7&"'!$L$21") -> 0 | AJ7: =sum(INDIRECT("'"&A7&"'!$K$17:$K$21")) -> 0 | AK7: =sum(INDIRECT("'"&A7&"'!$G$17:$G$21")) -> 30 | AL7: =average(AE7:AI7) -> 0 | AM7: =M7+T7+AB7+AJ7 -> 0 | AN7: =AM7/(N7+U7+AC7+AK7) -> 0 | AO7: =(N7+U7+AB7+AK7)*AP7 -> 93.958333 | AP7: =(F7-6.5)/4 -> 1.1458333
A8: ='Escoteiro 6'!C1 -> Escoteiro 6 | B8: Chefe 2 | C8: Patrulha 4 | D8: Acolhimento | E8: 42010 | F8: =DATEDIF(E8,TODAY(),"M")/12 -> 11.083333 | G8: =datedif(E8,today(),"Y")&" a "&datedif(E8,today(),"YM")&" m" -> 11 a 1 m | H8: =AO8-AM8 -> 93.958333 | I8: =INDIRECT("'"&A8&"'!$L$4") -> 0 | J8: =INDIRECT("'"&A8&"'!$L$5") -> 0 | K8: =INDIRECT("'"&A8&"'!$L$6") -> 0 | L8: =INDIRECT("'"&A8&"'!$L$7") -> 0 | M8: =sum(INDIRECT("'"&A8&"'!$K$4:$K$7")) -> 0 | N8: =sum(INDIRECT("'"&A8&"'!$G$4:$G$7")) -> 23 | O8: =average(I8:L8) -> 0 | P8: =INDIRECT("'"&A8&"'!$L$8") -> 0 | Q8: =INDIRECT("'"&A8&"'!$L$9") -> 0 | R8: =INDIRECT("'"&A8&"'!$L$10") -> 0 | S8: =INDIRECT("'"&A8&"'!$L$11") -> 0 | T8: =sum(INDIRECT("'"&A8&"'!$K$8:$K$11")) -> 0 | U8: =sum(INDIRECT("'"&A8&"'!$G$8:$G$11")) -> 29 | V8: =average(P8:S8) -> 0 | W8: =INDIRECT("'"&A8&"'!$L$12") -> 0 | X8: =INDIRECT("'"&A8&"'!$L$13") -> 0 | Y8: =INDIRECT("'"&A8&"'!$L$14") -> 0 | Z8: =INDIRECT("'"&A8&"'!$L$15") -> 0 | AA8: =INDIRECT("'"&A8&"'!$L$16") -> 0 | AB8: =sum(INDIRECT("'"&A8&"'!$K$12:$K$16")) -> 0 | AC8: =sum(INDIRECT("'"&A8&"'!$G$12:$G$16")) -> 28 | AD8: =average(W8:AA8) -> 0 | AE8: =INDIRECT("'"&A8&"'!$L$17") -> 0 | AF8: =INDIRECT("'"&A8&"'!$L$18") -> 0 | AG8: =INDIRECT("'"&A8&"'!$L$19") -> 0 | AH8: =INDIRECT("'"&A8&"'!$L$20") -> 0 | AI8: =INDIRECT("'"&A8&"'!$L$21") -> 0 | AJ8: =sum(INDIRECT("'"&A8&"'!$K$17:$K$21")) -> 0 | AK8: =sum(INDIRECT("'"&A8&"'!$G$17:$G$21")) -> 30 | AL8: =average(AE8:AI8) -> 0 | AM8: =M8+T8+AB8+AJ8 -> 0 | AN8: =AM8/(N8+U8+AC8+AK8) -> 0 | AO8: =(N8+U8+AB8+AK8)*AP8 -> 93.958333 | AP8: =(F8-6.5)/4 -> 1.1458333
A9: ='Escoteiro 7'!C1 -> Escoteiro 7 | B9: Chefe 2 | C9: Patrulha 3 | D9: Rumo | E9: 42011 | F9: =DATEDIF(E9,TODAY(),"M")/12 -> 11.083333 | G9: =datedif(E9,today(),"Y")&" a "&datedif(E9,today(),"YM")&" m" -> 11 a 1 m | H9: =AO9-AM9 -> 93.958333 | I9: =INDIRECT("'"&A9&"'!$L$4") -> 0 | J9: =INDIRECT("'"&A9&"'!$L$5") -> 0 | K9: =INDIRECT("'"&A9&"'!$L$6") -> 0 | L9: =INDIRECT("'"&A9&"'!$L$7") -> 0 | M9: =sum(INDIRECT("'"&A9&"'!$K$4:$K$7")) -> 0 | N9: =sum(INDIRECT("'"&A9&"'!$G$4:$G$7")) -> 23 | O9: =average(I9:L9) -> 0 | P9: =INDIRECT("'"&A9&"'!$L$8") -> 0 | Q9: =INDIRECT("'"&A9&"'!$L$9") -> 0 | R9: =INDIRECT("'"&A9&"'!$L$10") -> 0 | S9: =INDIRECT("'"&A9&"'!$L$11") -> 0 | T9: =sum(INDIRECT("'"&A9&"'!$K$8:$K$11")) -> 0 | U9: =sum(INDIRECT("'"&A9&"'!$G$8:$G$11")) -> 29 | V9: =average(P9:S9) -> 0 | W9: =INDIRECT("'"&A9&"'!$L$12") -> 0 | X9: =INDIRECT("'"&A9&"'!$L$13") -> 0 | Y9: =INDIRECT("'"&A9&"'!$L$14") -> 0 | Z9: =INDIRECT("'"&A9&"'!$L$15") -> 0 | AA9: =INDIRECT("'"&A9&"'!$L$16") -> 0 | AB9: =sum(INDIRECT("'"&A9&"'!$K$12:$K$16")) -> 0 | AC9: =sum(INDIRECT("'"&A9&"'!$G$12:$G$16")) -> 28 | AD9: =average(W9:AA9) -> 0 | AE9: =INDIRECT("'"&A9&"'!$L$17") -> 0 | AF9: =INDIRECT("'"&A9&"'!$L$18") -> 0 | AG9: =INDIRECT("'"&A9&"'!$L$19") -> 0 | AH9: =INDIRECT("'"&A9&"'!$L$20") -> 0 | AI9: =INDIRECT("'"&A9&"'!$L$21") -> 0 | AJ9: =sum(INDIRECT("'"&A9&"'!$K$17:$K$21")) -> 0 | AK9: =sum(INDIRECT("'"&A9&"'!$G$17:$G$21")) -> 30 | AL9: =average(AE9:AI9) -> 0 | AM9: =M9+T9+AB9+AJ9 -> 0 | AN9: =AM9/(N9+U9+AC9+AK9) -> 0 | AO9: =(N9+U9+AB9+AK9)*AP9 -> 93.958333 | AP9: =(F9-6.5)/4 -> 1.1458333
A10: ='Escoteiro 8'!C1 -> Escoteiro 8 | B10: Chefe 2 | C10: Patrulha 1 | D10: Rumo | E10: 42012 | F10: =DATEDIF(E10,TODAY(),"M")/12 -> 11.083333 | G10: =datedif(E10,today(),"Y")&" a "&datedif(E10,today(),"YM")&" m" -> 11 a 1 m | H10: =AO10-AM10 -> 93.958333 | I10: =INDIRECT("'"&A10&"'!$L$4") -> 0 | J10: =INDIRECT("'"&A10&"'!$L$5") -> 0 | K10: =INDIRECT("'"&A10&"'!$L$6") -> 0 | L10: =INDIRECT("'"&A10&"'!$L$7") -> 0 | M10: =sum(INDIRECT("'"&A10&"'!$K$4:$K$7")) -> 0 | N10: =sum(INDIRECT("'"&A10&"'!$G$4:$G$7")) -> 23 | O10: =average(I10:L10) -> 0 | P10: =INDIRECT("'"&A10&"'!$L$8") -> 0 | Q10: =INDIRECT("'"&A10&"'!$L$9") -> 0 | R10: =INDIRECT("'"&A10&"'!$L$10") -> 0 | S10: =INDIRECT("'"&A10&"'!$L$11") -> 0 | T10: =sum(INDIRECT("'"&A10&"'!$K$8:$K$11")) -> 0 | U10: =sum(INDIRECT("'"&A10&"'!$G$8:$G$11")) -> 29 | V10: =average(P10:S10) -> 0 | W10: =INDIRECT("'"&A10&"'!$L$12") -> 0 | X10: =INDIRECT("'"&A10&"'!$L$13") -> 0 | Y10: =INDIRECT("'"&A10&"'!$L$14") -> 0 | Z10: =INDIRECT("'"&A10&"'!$L$15") -> 0 | AA10: =INDIRECT("'"&A10&"'!$L$16") -> 0 | AB10: =sum(INDIRECT("'"&A10&"'!$K$12:$K$16")) -> 0 | AC10: =sum(INDIRECT("'"&A10&"'!$G$12:$G$16")) -> 28 | AD10: =average(W10:AA10) -> 0 | AE10: =INDIRECT("'"&A10&"'!$L$17") -> 0 | AF10: =INDIRECT("'"&A10&"'!$L$18") -> 0 | AG10: =INDIRECT("'"&A10&"'!$L$19") -> 0 | AH10: =INDIRECT("'"&A10&"'!$L$20") -> 0 | AI10: =INDIRECT("'"&A10&"'!$L$21") -> 0 | AJ10: =sum(INDIRECT("'"&A10&"'!$K$17:$K$21")) -> 0 | AK10: =sum(INDIRECT("'"&A10&"'!$G$17:$G$21")) -> 30 | AL10: =average(AE10:AI10) -> 0 | AM10: =M10+T10+AB10+AJ10 -> 0 | AN10: =AM10/(N10+U10+AC10+AK10) -> 0 | AO10: =(N10+U10+AB10+AK10)*AP10 -> 93.958333 | AP10: =(F10-6.5)/4 -> 1.1458333
A11: ='Escoteiro 9'!C1 -> Escoteiro 9 | B11: Chefe 2 | C11: Patrulha 3 | D11: Rumo | E11: 42013 | F11: =DATEDIF(E11,TODAY(),"M")/12 -> 11.083333 | G11: =datedif(E11,today(),"Y")&" a "&datedif(E11,today(),"YM")&" m" -> 11 a 1 m | H11: =AO11-AM11 -> 93.958333 | I11: =INDIRECT("'"&A11&"'!$L$4") -> 0 | J11: =INDIRECT("'"&A11&"'!$L$5") -> 0 | K11: =INDIRECT("'"&A11&"'!$L$6") -> 0 | L11: =INDIRECT("'"&A11&"'!$L$7") -> 0 | M11: =sum(INDIRECT("'"&A11&"'!$K$4:$K$7")) -> 0 | N11: =sum(INDIRECT("'"&A11&"'!$G$4:$G$7")) -> 23 | O11: =average(I11:L11) -> 0 | P11: =INDIRECT("'"&A11&"'!$L$8") -> 0 | Q11: =INDIRECT("'"&A11&"'!$L$9") -> 0 | R11: =INDIRECT("'"&A11&"'!$L$10") -> 0 | S11: =INDIRECT("'"&A11&"'!$L$11") -> 0 | T11: =sum(INDIRECT("'"&A11&"'!$K$8:$K$11")) -> 0 | U11: =sum(INDIRECT("'"&A11&"'!$G$8:$G$11")) -> 29 | V11: =average(P11:S11) -> 0 | W11: =INDIRECT("'"&A11&"'!$L$12") -> 0 | X11: =INDIRECT("'"&A11&"'!$L$13") -> 0 | Y11: =INDIRECT("'"&A11&"'!$L$14") -> 0 | Z11: =INDIRECT("'"&A11&"'!$L$15") -> 0 | AA11: =INDIRECT("'"&A11&"'!$L$16") -> 0 | AB11: =sum(INDIRECT("'"&A11&"'!$K$12:$K$16")) -> 0 | AC11: =sum(INDIRECT("'"&A11&"'!$G$12:$G$16")) -> 28 | AD11: =average(W11:AA11) -> 0 | AE11: =INDIRECT("'"&A11&"'!$L$17") -> 0 | AF11: =INDIRECT("'"&A11&"'!$L$18") -> 0 | AG11: =INDIRECT("'"&A11&"'!$L$19") -> 0 | AH11: =INDIRECT("'"&A11&"'!$L$20") -> 0 | AI11: =INDIRECT("'"&A11&"'!$L$21") -> 0 | AJ11: =sum(INDIRECT("'"&A11&"'!$K$17:$K$21")) -> 0 | AK11: =sum(INDIRECT("'"&A11&"'!$G$17:$G$21")) -> 30 | AL11: =average(AE11:AI11) -> 0 | AM11: =M11+T11+AB11+AJ11 -> 0 | AN11: =AM11/(N11+U11+AC11+AK11) -> 0 | AO11: =(N11+U11+AB11+AK11)*AP11 -> 93.958333 | AP11: =(F11-6.5)/4 -> 1.1458333
A12: ='Escoteiro 10'!C1 -> Escoteiro 10 | B12: Chefe 3 | C12: Patrulha 4 | D12: Pistas | E12: 42014 | F12: =DATEDIF(E12,TODAY(),"M")/12 -> 11.083333 | G12: =datedif(E12,today(),"Y")&" a "&datedif(E12,today(),"YM")&" m" -> 11 a 1 m | H12: =AO12-AM12 -> 93.958333 | I12: =INDIRECT("'"&A12&"'!$L$4") -> 0 | J12: =INDIRECT("'"&A12&"'!$L$5") -> 0 | K12: =INDIRECT("'"&A12&"'!$L$6") -> 0 | L12: =INDIRECT("'"&A12&"'!$L$7") -> 0 | M12: =sum(INDIRECT("'"&A12&"'!$K$4:$K$7")) -> 0 | N12: =sum(INDIRECT("'"&A12&"'!$G$4:$G$7")) -> 23 | O12: =average(I12:L12) -> 0 | P12: =INDIRECT("'"&A12&"'!$L$8") -> 0 | Q12: =INDIRECT("'"&A12&"'!$L$9") -> 0 | R12: =INDIRECT("'"&A12&"'!$L$10") -> 0 | S12: =INDIRECT("'"&A12&"'!$L$11") -> 0 | T12: =sum(INDIRECT("'"&A12&"'!$K$8:$K$11")) -> 0 | U12: =sum(INDIRECT("'"&A12&"'!$G$8:$G$11")) -> 29 | V12: =average(P12:S12) -> 0 | W12: =INDIRECT("'"&A12&"'!$L$12") -> 0 | X12: =INDIRECT("'"&A12&"'!$L$13") -> 0 | Y12: =INDIRECT("'"&A12&"'!$L$14") -> 0 | Z12: =INDIRECT("'"&A12&"'!$L$15") -> 0 | AA12: =INDIRECT("'"&A12&"'!$L$16") -> 0 | AB12: =sum(INDIRECT("'"&A12&"'!$K$12:$K$16")) -> 0 | AC12: =sum(INDIRECT("'"&A12&"'!$G$12:$G$16")) -> 28 | AD12: =average(W12:AA12) -> 0 | AE12: =INDIRECT("'"&A12&"'!$L$17") -> 0 | AF12: =INDIRECT("'"&A12&"'!$L$18") -> 0 | AG12: =INDIRECT("'"&A12&"'!$L$19") -> 0 | AH12: =INDIRECT("'"&A12&"'!$L$20") -> 0 | AI12: =INDIRECT("'"&A12&"'!$L$21") -> 0 | AJ12: =sum(INDIRECT("'"&A12&"'!$K$17:$K$21")) -> 0 | AK12: =sum(INDIRECT("'"&A12&"'!$G$17:$G$21")) -> 30 | AL12: =average(AE12:AI12) -> 0 | AM12: =M12+T12+AB12+AJ12 -> 0 | AN12: =AM12/(N12+U12+AC12+AK12) -> 0 | AO12: =(N12+U12+AB12+AK12)*AP12 -> 93.958333 | AP12: =(F12-6.5)/4 -> 1.1458333
A13: ='Escoteiro 11'!C1 -> Escoteiro 11 | B13: Chefe 3 | C13: Patrulha 4 | D13: Travessia | E13: 42015 | F13: =DATEDIF(E13,TODAY(),"M")/12 -> 11.083333 | G13: =datedif(E13,today(),"Y")&" a "&datedif(E13,today(),"YM")&" m" -> 11 a 1 m | H13: =AO13-AM13 -> 93.958333 | I13: =INDIRECT("'"&A13&"'!$L$4") -> 0 | J13: =INDIRECT("'"&A13&"'!$L$5") -> 0 | K13: =INDIRECT("'"&A13&"'!$L$6") -> 0 | L13: =INDIRECT("'"&A13&"'!$L$7") -> 0 | M13: =sum(INDIRECT("'"&A13&"'!$K$4:$K$7")) -> 0 | N13: =sum(INDIRECT("'"&A13&"'!$G$4:$G$7")) -> 23 | O13: =average(I13:L13) -> 0 | P13: =INDIRECT("'"&A13&"'!$L$8") -> 0 | Q13: =INDIRECT("'"&A13&"'!$L$9") -> 0 | R13: =INDIRECT("'"&A13&"'!$L$10") -> 0 | S13: =INDIRECT("'"&A13&"'!$L$11") -> 0 | T13: =sum(INDIRECT("'"&A13&"'!$K$8:$K$11")) -> 0 | U13: =sum(INDIRECT("'"&A13&"'!$G$8:$G$11")) -> 29 | V13: =average(P13:S13) -> 0 | W13: =INDIRECT("'"&A13&"'!$L$12") -> 0 | X13: =INDIRECT("'"&A13&"'!$L$13") -> 0 | Y13: =INDIRECT("'"&A13&"'!$L$14") -> 0 | Z13: =INDIRECT("'"&A13&"'!$L$15") -> 0 | AA13: =INDIRECT("'"&A13&"'!$L$16") -> 0 | AB13: =sum(INDIRECT("'"&A13&"'!$K$12:$K$16")) -> 0 | AC13: =sum(INDIRECT("'"&A13&"'!$G$12:$G$16")) -> 28 | AD13: =average(W13:AA13) -> 0 | AE13: =INDIRECT("'"&A13&"'!$L$17") -> 0 | AF13: =INDIRECT("'"&A13&"'!$L$18") -> 0 | AG13: =INDIRECT("'"&A13&"'!$L$19") -> 0 | AH13: =INDIRECT("'"&A13&"'!$L$20") -> 0 | AI13: =INDIRECT("'"&A13&"'!$L$21") -> 0 | AJ13: =sum(INDIRECT("'"&A13&"'!$K$17:$K$21")) -> 0 | AK13: =sum(INDIRECT("'"&A13&"'!$G$17:$G$21")) -> 30 | AL13: =average(AE13:AI13) -> 0 | AM13: =M13+T13+AB13+AJ13 -> 0 | AN13: =AM13/(N13+U13+AC13+AK13) -> 0 | AO13: =(N13+U13+AB13+AK13)*AP13 -> 93.958333 | AP13: =(F13-6.5)/4 -> 1.1458333
A14: ='Escoteiro 12'!C1 -> Escoteiro 12 | B14: Chefe 3 | C14: Patrulha 2 | D14: Travessia | E14: 42016 | F14: =DATEDIF(E14,TODAY(),"M")/12 -> 11.083333 | G14: =datedif(E14,today(),"Y")&" a "&datedif(E14,today(),"YM")&" m" -> 11 a 1 m | H14: =AO14-AM14 -> 93.958333 | I14: =INDIRECT("'"&A14&"'!$L$4") -> 0 | J14: =INDIRECT("'"&A14&"'!$L$5") -> 0 | K14: =INDIRECT("'"&A14&"'!$L$6") -> 0 | L14: =INDIRECT("'"&A14&"'!$L$7") -> 0 | M14: =sum(INDIRECT("'"&A14&"'!$K$4:$K$7")) -> 0 | N14: =sum(INDIRECT("'"&A14&"'!$G$4:$G$7")) -> 23 | O14: =average(I14:L14) -> 0 | P14: =INDIRECT("'"&A14&"'!$L$8") -> 0 | Q14: =INDIRECT("'"&A14&"'!$L$9") -> 0 | R14: =INDIRECT("'"&A14&"'!$L$10") -> 0 | S14: =INDIRECT("'"&A14&"'!$L$11") -> 0 | T14: =sum(INDIRECT("'"&A14&"'!$K$8:$K$11")) -> 0 | U14: =sum(INDIRECT("'"&A14&"'!$G$8:$G$11")) -> 29 | V14: =average(P14:S14) -> 0 | W14: =INDIRECT("'"&A14&"'!$L$12") -> 0 | X14: =INDIRECT("'"&A14&"'!$L$13") -> 0 | Y14: =INDIRECT("'"&A14&"'!$L$14") -> 0 | Z14: =INDIRECT("'"&A14&"'!$L$15") -> 0 | AA14: =INDIRECT("'"&A14&"'!$L$16") -> 0 | AB14: =sum(INDIRECT("'"&A14&"'!$K$12:$K$16")) -> 0 | AC14: =sum(INDIRECT("'"&A14&"'!$G$12:$G$16")) -> 28 | AD14: =average(W14:AA14) -> 0 | AE14: =INDIRECT("'"&A14&"'!$L$17") -> 0 | AF14: =INDIRECT("'"&A14&"'!$L$18") -> 0 | AG14: =INDIRECT("'"&A14&"'!$L$19") -> 0 | AH14: =INDIRECT("'"&A14&"'!$L$20") -> 0 | AI14: =INDIRECT("'"&A14&"'!$L$21") -> 0 | AJ14: =sum(INDIRECT("'"&A14&"'!$K$17:$K$21")) -> 0 | AK14: =sum(INDIRECT("'"&A14&"'!$G$17:$G$21")) -> 30 | AL14: =average(AE14:AI14) -> 0 | AM14: =M14+T14+AB14+AJ14 -> 0 | AN14: =AM14/(N14+U14+AC14+AK14) -> 0 | AO14: =(N14+U14+AB14+AK14)*AP14 -> 93.958333 | AP14: =(F14-6.5)/4 -> 1.1458333
A15: ='Escoteiro 13'!C1 -> Escoteiro 13 | B15: Chefe 1 | C15: Patrulha 1 | D15: Caminho | E15: 42017 | F15: =DATEDIF(E15,TODAY(),"M")/12 -> 11.083333 | G15: =datedif(E15,today(),"Y")&" a "&datedif(E15,today(),"YM")&" m" -> 11 a 1 m | H15: =AO15-AM15 -> 93.958333 | I15: =INDIRECT("'"&A15&"'!$L$4") -> 0 | J15: =INDIRECT("'"&A15&"'!$L$5") -> 0 | K15: =INDIRECT("'"&A15&"'!$L$6") -> 0 | L15: =INDIRECT("'"&A15&"'!$L$7") -> 0 | M15: =sum(INDIRECT("'"&A15&"'!$K$4:$K$7")) -> 0 | N15: =sum(INDIRECT("'"&A15&"'!$G$4:$G$7")) -> 23 | O15: =average(I15:L15) -> 0 | P15: =INDIRECT("'"&A15&"'!$L$8") -> 0 | Q15: =INDIRECT("'"&A15&"'!$L$9") -> 0 | R15: =INDIRECT("'"&A15&"'!$L$10") -> 0 | S15: =INDIRECT("'"&A15&"'!$L$11") -> 0 | T15: =sum(INDIRECT("'"&A15&"'!$K$8:$K$11")) -> 0 | U15: =sum(INDIRECT("'"&A15&"'!$G$8:$G$11")) -> 29 | V15: =average(P15:S15) -> 0 | W15: =INDIRECT("'"&A15&"'!$L$12") -> 0 | X15: =INDIRECT("'"&A15&"'!$L$13") -> 0 | Y15: =INDIRECT("'"&A15&"'!$L$14") -> 0 | Z15: =INDIRECT("'"&A15&"'!$L$15") -> 0 | AA15: =INDIRECT("'"&A15&"'!$L$16") -> 0 | AB15: =sum(INDIRECT("'"&A15&"'!$K$12:$K$16")) -> 0 | AC15: =sum(INDIRECT("'"&A15&"'!$G$12:$G$16")) -> 28 | AD15: =average(W15:AA15) -> 0 | AE15: =INDIRECT("'"&A15&"'!$L$17") -> 0 | AF15: =INDIRECT("'"&A15&"'!$L$18") -> 0 | AG15: =INDIRECT("'"&A15&"'!$L$19") -> 0 | AH15: =INDIRECT("'"&A15&"'!$L$20") -> 0 | AI15: =INDIRECT("'"&A15&"'!$L$21") -> 0 | AJ15: =sum(INDIRECT("'"&A15&"'!$K$17:$K$21")) -> 0 | AK15: =sum(INDIRECT("'"&A15&"'!$G$17:$G$21")) -> 30 | AL15: =average(AE15:AI15) -> 0 | AM15: =M15+T15+AB15+AJ15 -> 0 | AN15: =AM15/(N15+U15+AC15+AK15) -> 0 | AO15: =(N15+U15+AB15+AK15)*AP15 -> 93.958333 | AP15: =(F15-6.5)/4 -> 1.1458333
A16: ='Escoteiro 14'!C1 -> Escoteiro 14 | B16: Chefe 1 | C16: Patrulha 2 | D16: Caminho | E16: 42018 | F16: =DATEDIF(E16,TODAY(),"M")/12 -> 11 | G16: =datedif(E16,today(),"Y")&" a "&datedif(E16,today(),"YM")&" m" -> 11 a 0 m | H16: =AO16-AM16 -> 92.25 | I16: =INDIRECT("'"&A16&"'!$L$4") -> 0 | J16: =INDIRECT("'"&A16&"'!$L$5") -> 0 | K16: =INDIRECT("'"&A16&"'!$L$6") -> 0 | L16: =INDIRECT("'"&A16&"'!$L$7") -> 0 | M16: =sum(INDIRECT("'"&A16&"'!$K$4:$K$7")) -> 0 | N16: =sum(INDIRECT("'"&A16&"'!$G$4:$G$7")) -> 23 | O16: =average(I16:L16) -> 0 | P16: =INDIRECT("'"&A16&"'!$L$8") -> 0 | Q16: =INDIRECT("'"&A16&"'!$L$9") -> 0 | R16: =INDIRECT("'"&A16&"'!$L$10") -> 0 | S16: =INDIRECT("'"&A16&"'!$L$11") -> 0 | T16: =sum(INDIRECT("'"&A16&"'!$K$8:$K$11")) -> 0 | U16: =sum(INDIRECT("'"&A16&"'!$G$8:$G$11")) -> 29 | V16: =average(P16:S16) -> 0 | W16: =INDIRECT("'"&A16&"'!$L$12") -> 0 | X16: =INDIRECT("'"&A16&"'!$L$13") -> 0 | Y16: =INDIRECT("'"&A16&"'!$L$14") -> 0 | Z16: =INDIRECT("'"&A16&"'!$L$15") -> 0 | AA16: =INDIRECT("'"&A16&"'!$L$16") -> 0 | AB16: =sum(INDIRECT("'"&A16&"'!$K$12:$K$16")) -> 0 | AC16: =sum(INDIRECT("'"&A16&"'!$G$12:$G$16")) -> 28 | AD16: =average(W16:AA16) -> 0 | AE16: =INDIRECT("'"&A16&"'!$L$17") -> 0 | AF16: =INDIRECT("'"&A16&"'!$L$18") -> 0 | AG16: =INDIRECT("'"&A16&"'!$L$19") -> 0 | AH16: =INDIRECT("'"&A16&"'!$L$20") -> 0 | AI16: =INDIRECT("'"&A16&"'!$L$21") -> 0 | AJ16: =sum(INDIRECT("'"&A16&"'!$K$17:$K$21")) -> 0 | AK16: =sum(INDIRECT("'"&A16&"'!$G$17:$G$21")) -> 30 | AL16: =average(AE16:AI16) -> 0 | AM16: =M16+T16+AB16+AJ16 -> 0 | AN16: =AM16/(N16+U16+AC16+AK16) -> 0 | AO16: =(N16+U16+AB16+AK16)*AP16 -> 92.25 | AP16: =(F16-6.5)/4 -> 1.125
A17: ='Escoteiro 15'!C1 -> Escoteiro 15 | B17: Chefe 1 | C17: Patrulha 3 | D17: Caminho | E17: 42019 | F17: =DATEDIF(E17,TODAY(),"M")/12 -> 11 | G17: =datedif(E17,today(),"Y")&" a "&datedif(E17,today(),"YM")&" m" -> 11 a 0 m | H17: =AO17-AM17 -> 92.25 | I17: =INDIRECT("'"&A17&"'!$L$4") -> 0 | J17: =INDIRECT("'"&A17&"'!$L$5") -> 0 | K17: =INDIRECT("'"&A17&"'!$L$6") -> 0 | L17: =INDIRECT("'"&A17&"'!$L$7") -> 0 | M17: =sum(INDIRECT("'"&A17&"'!$K$4:$K$7")) -> 0 | N17: =sum(INDIRECT("'"&A17&"'!$G$4:$G$7")) -> 23 | O17: =average(I17:L17) -> 0 | P17: =INDIRECT("'"&A17&"'!$L$8") -> 0 | Q17: =INDIRECT("'"&A17&"'!$L$9") -> 0 | R17: =INDIRECT("'"&A17&"'!$L$10") -> 0 | S17: =INDIRECT("'"&A17&"'!$L$11") -> 0 | T17: =sum(INDIRECT("'"&A17&"'!$K$8:$K$11")) -> 0 | U17: =sum(INDIRECT("'"&A17&"'!$G$8:$G$11")) -> 29 | V17: =average(P17:S17) -> 0 | W17: =INDIRECT("'"&A17&"'!$L$12") -> 0 | X17: =INDIRECT("'"&A17&"'!$L$13") -> 0 | Y17: =INDIRECT("'"&A17&"'!$L$14") -> 0 | Z17: =INDIRECT("'"&A17&"'!$L$15") -> 0 | AA17: =INDIRECT("'"&A17&"'!$L$16") -> 0 | AB17: =sum(INDIRECT("'"&A17&"'!$K$12:$K$16")) -> 0 | AC17: =sum(INDIRECT("'"&A17&"'!$G$12:$G$16")) -> 28 | AD17: =average(W17:AA17) -> 0 | AE17: =INDIRECT("'"&A17&"'!$L$17") -> 0 | AF17: =INDIRECT("'"&A17&"'!$L$18") -> 0 | AG17: =INDIRECT("'"&A17&"'!$L$19") -> 0 | AH17: =INDIRECT("'"&A17&"'!$L$20") -> 0 | AI17: =INDIRECT("'"&A17&"'!$L$21") -> 0 | AJ17: =sum(INDIRECT("'"&A17&"'!$K$17:$K$21")) -> 0 | AK17: =sum(INDIRECT("'"&A17&"'!$G$17:$G$21")) -> 30 | AL17: =average(AE17:AI17) -> 0 | AM17: =M17+T17+AB17+AJ17 -> 0 | AN17: =AM17/(N17+U17+AC17+AK17) -> 0 | AO17: =(N17+U17+AB17+AK17)*AP17 -> 92.25 | AP17: =(F17-6.5)/4 -> 1.125
A18: ='Escoteiro 16'!C1 -> Escoteiro 16 | B18: Chefe 1 | C18: Patrulha 1 | D18: Caminho | E18: 42020 | F18: =DATEDIF(E18,TODAY(),"M")/12 -> 11 | G18: =datedif(E18,today(),"Y")&" a "&datedif(E18,today(),"YM")&" m" -> 11 a 0 m | H18: =AO18-AM18 -> 92.25 | I18: =INDIRECT("'"&A18&"'!$L$4") -> 0 | J18: =INDIRECT("'"&A18&"'!$L$5") -> 0 | K18: =INDIRECT("'"&A18&"'!$L$6") -> 0 | L18: =INDIRECT("'"&A18&"'!$L$7") -> 0 | M18: =sum(INDIRECT("'"&A18&"'!$K$4:$K$7")) -> 0 | N18: =sum(INDIRECT("'"&A18&"'!$G$4:$G$7")) -> 23 | O18: =average(I18:L18) -> 0 | P18: =INDIRECT("'"&A18&"'!$L$8") -> 0 | Q18: =INDIRECT("'"&A18&"'!$L$9") -> 0 | R18: =INDIRECT("'"&A18&"'!$L$10") -> 0 | S18: =INDIRECT("'"&A18&"'!$L$11") -> 0 | T18: =sum(INDIRECT("'"&A18&"'!$K$8:$K$11")) -> 0 | U18: =sum(INDIRECT("'"&A18&"'!$G$8:$G$11")) -> 29 | V18: =average(P18:S18) -> 0 | W18: =INDIRECT("'"&A18&"'!$L$12") -> 0 | X18: =INDIRECT("'"&A18&"'!$L$13") -> 0 | Y18: =INDIRECT("'"&A18&"'!$L$14") -> 0 | Z18: =INDIRECT("'"&A18&"'!$L$15") -> 0 | AA18: =INDIRECT("'"&A18&"'!$L$16") -> 0 | AB18: =sum(INDIRECT("'"&A18&"'!$K$12:$K$16")) -> 0 | AC18: =sum(INDIRECT("'"&A18&"'!$G$12:$G$16")) -> 28 | AD18: =average(W18:AA18) -> 0 | AE18: =INDIRECT("'"&A18&"'!$L$17") -> 0 | AF18: =INDIRECT("'"&A18&"'!$L$18") -> 0 | AG18: =INDIRECT("'"&A18&"'!$L$19") -> 0 | AH18: =INDIRECT("'"&A18&"'!$L$20") -> 0 | AI18: =INDIRECT("'"&A18&"'!$L$21") -> 0 | AJ18: =sum(INDIRECT("'"&A18&"'!$K$17:$K$21")) -> 0 | AK18: =sum(INDIRECT("'"&A18&"'!$G$17:$G$21")) -> 30 | AL18: =average(AE18:AI18) -> 0 | AM18: =M18+T18+AB18+AJ18 -> 0 | AN18: =AM18/(N18+U18+AC18+AK18) -> 0 | AO18: =(N18+U18+AB18+AK18)*AP18 -> 92.25 | AP18: =(F18-6.5)/4 -> 1.125
A19: ='Escoteiro 17'!C1 -> Escoteiro 17 | B19: Chefe 1 | C19: Patrulha 2 | D19: Caminho | E19: 42021 | F19: =DATEDIF(E19,TODAY(),"M")/12 -> 11 | G19: =datedif(E19,today(),"Y")&" a "&datedif(E19,today(),"YM")&" m" -> 11 a 0 m | H19: =AO19-AM19 -> 92.25 | I19: =INDIRECT("'"&A19&"'!$L$4") -> 0 | J19: =INDIRECT("'"&A19&"'!$L$5") -> 0 | K19: =INDIRECT("'"&A19&"'!$L$6") -> 0 | L19: =INDIRECT("'"&A19&"'!$L$7") -> 0 | M19: =sum(INDIRECT("'"&A19&"'!$K$4:$K$7")) -> 0 | N19: =sum(INDIRECT("'"&A19&"'!$G$4:$G$7")) -> 23 | O19: =average(I19:L19) -> 0 | P19: =INDIRECT("'"&A19&"'!$L$8") -> 0 | Q19: =INDIRECT("'"&A19&"'!$L$9") -> 0 | R19: =INDIRECT("'"&A19&"'!$L$10") -> 0 | S19: =INDIRECT("'"&A19&"'!$L$11") -> 0 | T19: =sum(INDIRECT("'"&A19&"'!$K$8:$K$11")) -> 0 | U19: =sum(INDIRECT("'"&A19&"'!$G$8:$G$11")) -> 29 | V19: =average(P19:S19) -> 0 | W19: =INDIRECT("'"&A19&"'!$L$12") -> 0 | X19: =INDIRECT("'"&A19&"'!$L$13") -> 0 | Y19: =INDIRECT("'"&A19&"'!$L$14") -> 0 | Z19: =INDIRECT("'"&A19&"'!$L$15") -> 0 | AA19: =INDIRECT("'"&A19&"'!$L$16") -> 0 | AB19: =sum(INDIRECT("'"&A19&"'!$K$12:$K$16")) -> 0 | AC19: =sum(INDIRECT("'"&A19&"'!$G$12:$G$16")) -> 28 | AD19: =average(W19:AA19) -> 0 | AE19: =INDIRECT("'"&A19&"'!$L$17") -> 0 | AF19: =INDIRECT("'"&A19&"'!$L$18") -> 0 | AG19: =INDIRECT("'"&A19&"'!$L$19") -> 0 | AH19: =INDIRECT("'"&A19&"'!$L$20") -> 0 | AI19: =INDIRECT("'"&A19&"'!$L$21") -> 0 | AJ19: =sum(INDIRECT("'"&A19&"'!$K$17:$K$21")) -> 0 | AK19: =sum(INDIRECT("'"&A19&"'!$G$17:$G$21")) -> 30 | AL19: =average(AE19:AI19) -> 0 | AM19: =M19+T19+AB19+AJ19 -> 0 | AN19: =AM19/(N19+U19+AC19+AK19) -> 0 | AO19: =(N19+U19+AB19+AK19)*AP19 -> 92.25 | AP19: =(F19-6.5)/4 -> 1.125
A20: ='Escoteiro 18'!C1 -> Escoteiro 18 | B20: Chefe 2 | C20: Patrulha 4 | D20: Caminho | E20: 42022 | F20: =DATEDIF(E20,TODAY(),"M")/12 -> 11 | G20: =datedif(E20,today(),"Y")&" a "&datedif(E20,today(),"YM")&" m" -> 11 a 0 m | H20: =AO20-AM20 -> 92.25 | I20: =INDIRECT("'"&A20&"'!$L$4") -> 0 | J20: =INDIRECT("'"&A20&"'!$L$5") -> 0 | K20: =INDIRECT("'"&A20&"'!$L$6") -> 0 | L20: =INDIRECT("'"&A20&"'!$L$7") -> 0 | M20: =sum(INDIRECT("'"&A20&"'!$K$4:$K$7")) -> 0 | N20: =sum(INDIRECT("'"&A20&"'!$G$4:$G$7")) -> 23 | O20: =average(I20:L20) -> 0 | P20: =INDIRECT("'"&A20&"'!$L$8") -> 0 | Q20: =INDIRECT("'"&A20&"'!$L$9") -> 0 | R20: =INDIRECT("'"&A20&"'!$L$10") -> 0 | S20: =INDIRECT("'"&A20&"'!$L$11") -> 0 | T20: =sum(INDIRECT("'"&A20&"'!$K$8:$K$11")) -> 0 | U20: =sum(INDIRECT("'"&A20&"'!$G$8:$G$11")) -> 29 | V20: =average(P20:S20) -> 0 | W20: =INDIRECT("'"&A20&"'!$L$12") -> 0 | X20: =INDIRECT("'"&A20&"'!$L$13") -> 0 | Y20: =INDIRECT("'"&A20&"'!$L$14") -> 0 | Z20: =INDIRECT("'"&A20&"'!$L$15") -> 0 | AA20: =INDIRECT("'"&A20&"'!$L$16") -> 0 | AB20: =sum(INDIRECT("'"&A20&"'!$K$12:$K$16")) -> 0 | AC20: =sum(INDIRECT("'"&A20&"'!$G$12:$G$16")) -> 28 | AD20: =average(W20:AA20) -> 0 | AE20: =INDIRECT("'"&A20&"'!$L$17") -> 0 | AF20: =INDIRECT("'"&A20&"'!$L$18") -> 0 | AG20: =INDIRECT("'"&A20&"'!$L$19") -> 0 | AH20: =INDIRECT("'"&A20&"'!$L$20") -> 0 | AI20: =INDIRECT("'"&A20&"'!$L$21") -> 0 | AJ20: =sum(INDIRECT("'"&A20&"'!$K$17:$K$21")) -> 0 | AK20: =sum(INDIRECT("'"&A20&"'!$G$17:$G$21")) -> 30 | AL20: =average(AE20:AI20) -> 0 | AM20: =M20+T20+AB20+AJ20 -> 0 | AN20: =AM20/(N20+U20+AC20+AK20) -> 0 | AO20: =(N20+U20+AB20+AK20)*AP20 -> 92.25 | AP20: =(F20-6.5)/4 -> 1.125
A21: ='Escoteiro 19'!C1 -> Escoteiro 19 | B21: Chefe 2 | C21: Patrulha 3 | D21: Caminho | E21: 42023 | F21: =DATEDIF(E21,TODAY(),"M")/12 -> 11 | G21: =datedif(E21,today(),"Y")&" a "&datedif(E21,today(),"YM")&" m" -> 11 a 0 m | H21: =AO21-AM21 -> 92.25 | I21: =INDIRECT("'"&A21&"'!$L$4") -> 0 | J21: =INDIRECT("'"&A21&"'!$L$5") -> 0 | K21: =INDIRECT("'"&A21&"'!$L$6") -> 0 | L21: =INDIRECT("'"&A21&"'!$L$7") -> 0 | M21: =sum(INDIRECT("'"&A21&"'!$K$4:$K$7")) -> 0 | N21: =sum(INDIRECT("'"&A21&"'!$G$4:$G$7")) -> 23 | O21: =average(I21:L21) -> 0 | P21: =INDIRECT("'"&A21&"'!$L$8") -> 0 | Q21: =INDIRECT("'"&A21&"'!$L$9") -> 0 | R21: =INDIRECT("'"&A21&"'!$L$10") -> 0 | S21: =INDIRECT("'"&A21&"'!$L$11") -> 0 | T21: =sum(INDIRECT("'"&A21&"'!$K$8:$K$11")) -> 0 | U21: =sum(INDIRECT("'"&A21&"'!$G$8:$G$11")) -> 29 | V21: =average(P21:S21) -> 0 | W21: =INDIRECT("'"&A21&"'!$L$12") -> 0 | X21: =INDIRECT("'"&A21&"'!$L$13") -> 0 | Y21: =INDIRECT("'"&A21&"'!$L$14") -> 0 | Z21: =INDIRECT("'"&A21&"'!$L$15") -> 0 | AA21: =INDIRECT("'"&A21&"'!$L$16") -> 0 | AB21: =sum(INDIRECT("'"&A21&"'!$K$12:$K$16")) -> 0 | AC21: =sum(INDIRECT("'"&A21&"'!$G$12:$G$16")) -> 28 | AD21: =average(W21:AA21) -> 0 | AE21: =INDIRECT("'"&A21&"'!$L$17") -> 0 | AF21: =INDIRECT("'"&A21&"'!$L$18") -> 0 | AG21: =INDIRECT("'"&A21&"'!$L$19") -> 0 | AH21: =INDIRECT("'"&A21&"'!$L$20") -> 0 | AI21: =INDIRECT("'"&A21&"'!$L$21") -> 0 | AJ21: =sum(INDIRECT("'"&A21&"'!$K$17:$K$21")) -> 0 | AK21: =sum(INDIRECT("'"&A21&"'!$G$17:$G$21")) -> 30 | AL21: =average(AE21:AI21) -> 0 | AM21: =M21+T21+AB21+AJ21 -> 0 | AN21: =AM21/(N21+U21+AC21+AK21) -> 0 | AO21: =(N21+U21+AB21+AK21)*AP21 -> 92.25 | AP21: =(F21-6.5)/4 -> 1.125
A22: ='Escoteiro 19'!C1 -> Escoteiro 19 | B22: Chefe 2 | C22: Patrulha 1 | D22: Caminho | E22: 42024 | F22: =DATEDIF(E22,TODAY(),"M")/12 -> 11 | G22: =datedif(E22,today(),"Y")&" a "&datedif(E22,today(),"YM")&" m" -> 11 a 0 m | H22: =AO22-AM22 -> 92.25 | I22: =INDIRECT("'"&A22&"'!$L$4") -> 0 | J22: =INDIRECT("'"&A22&"'!$L$5") -> 0 | K22: =INDIRECT("'"&A22&"'!$L$6") -> 0 | L22: =INDIRECT("'"&A22&"'!$L$7") -> 0 | M22: =sum(INDIRECT("'"&A22&"'!$K$4:$K$7")) -> 0 | N22: =sum(INDIRECT("'"&A22&"'!$G$4:$G$7")) -> 23 | O22: =average(I22:L22) -> 0 | P22: =INDIRECT("'"&A22&"'!$L$8") -> 0 | Q22: =INDIRECT("'"&A22&"'!$L$9") -> 0 | R22: =INDIRECT("'"&A22&"'!$L$10") -> 0 | S22: =INDIRECT("'"&A22&"'!$L$11") -> 0 | T22: =sum(INDIRECT("'"&A22&"'!$K$8:$K$11")) -> 0 | U22: =sum(INDIRECT("'"&A22&"'!$G$8:$G$11")) -> 29 | V22: =average(P22:S22) -> 0 | W22: =INDIRECT("'"&A22&"'!$L$12") -> 0 | X22: =INDIRECT("'"&A22&"'!$L$13") -> 0 | Y22: =INDIRECT("'"&A22&"'!$L$14") -> 0 | Z22: =INDIRECT("'"&A22&"'!$L$15") -> 0 | AA22: =INDIRECT("'"&A22&"'!$L$16") -> 0 | AB22: =sum(INDIRECT("'"&A22&"'!$K$12:$K$16")) -> 0 | AC22: =sum(INDIRECT("'"&A22&"'!$G$12:$G$16")) -> 28 | AD22: =average(W22:AA22) -> 0 | AE22: =INDIRECT("'"&A22&"'!$L$17") -> 0 | AF22: =INDIRECT("'"&A22&"'!$L$18") -> 0 | AG22: =INDIRECT("'"&A22&"'!$L$19") -> 0 | AH22: =INDIRECT("'"&A22&"'!$L$20") -> 0 | AI22: =INDIRECT("'"&A22&"'!$L$21") -> 0 | AJ22: =sum(INDIRECT("'"&A22&"'!$K$17:$K$21")) -> 0 | AK22: =sum(INDIRECT("'"&A22&"'!$G$17:$G$21")) -> 30 | AL22: =average(AE22:AI22) -> 0 | AM22: =M22+T22+AB22+AJ22 -> 0 | AN22: =AM22/(N22+U22+AC22+AK22) -> 0 | AO22: =(N22+U22+AB22+AK22)*AP22 -> 92.25 | AP22: =(F22-6.5)/4 -> 1.125
A23: ='Escoteiro 21'!C1 -> Escoteiro 21 | B23: Chefe 2 | C23: Patrulha 3 | D23: Caminho | E23: 42025 | F23: =DATEDIF(E23,TODAY(),"M")/12 -> 11 | G23: =datedif(E23,today(),"Y")&" a "&datedif(E23,today(),"YM")&" m" -> 11 a 0 m | H23: =AO23-AM23 -> 92.25 | I23: =INDIRECT("'"&A23&"'!$L$4") -> 0 | J23: =INDIRECT("'"&A23&"'!$L$5") -> 0 | K23: =INDIRECT("'"&A23&"'!$L$6") -> 0 | L23: =INDIRECT("'"&A23&"'!$L$7") -> 0 | M23: =sum(INDIRECT("'"&A23&"'!$K$4:$K$7")) -> 0 | N23: =sum(INDIRECT("'"&A23&"'!$G$4:$G$7")) -> 23 | O23: =average(I23:L23) -> 0 | P23: =INDIRECT("'"&A23&"'!$L$8") -> 0 | Q23: =INDIRECT("'"&A23&"'!$L$9") -> 0 | R23: =INDIRECT("'"&A23&"'!$L$10") -> 0 | S23: =INDIRECT("'"&A23&"'!$L$11") -> 0 | T23: =sum(INDIRECT("'"&A23&"'!$K$8:$K$11")) -> 0 | U23: =sum(INDIRECT("'"&A23&"'!$G$8:$G$11")) -> 29 | V23: =average(P23:S23) -> 0 | W23: =INDIRECT("'"&A23&"'!$L$12") -> 0 | X23: =INDIRECT("'"&A23&"'!$L$13") -> 0 | Y23: =INDIRECT("'"&A23&"'!$L$14") -> 0 | Z23: =INDIRECT("'"&A23&"'!$L$15") -> 0 | AA23: =INDIRECT("'"&A23&"'!$L$16") -> 0 | AB23: =sum(INDIRECT("'"&A23&"'!$K$12:$K$16")) -> 0 | AC23: =sum(INDIRECT("'"&A23&"'!$G$12:$G$16")) -> 28 | AD23: =average(W23:AA23) -> 0 | AE23: =INDIRECT("'"&A23&"'!$L$17") -> 0 | AF23: =INDIRECT("'"&A23&"'!$L$18") -> 0 | AG23: =INDIRECT("'"&A23&"'!$L$19") -> 0 | AH23: =INDIRECT("'"&A23&"'!$L$20") -> 0 | AI23: =INDIRECT("'"&A23&"'!$L$21") -> 0 | AJ23: =sum(INDIRECT("'"&A23&"'!$K$17:$K$21")) -> 0 | AK23: =sum(INDIRECT("'"&A23&"'!$G$17:$G$21")) -> 30 | AL23: =average(AE23:AI23) -> 0 | AM23: =M23+T23+AB23+AJ23 -> 0 | AN23: =AM23/(N23+U23+AC23+AK23) -> 0 | AO23: =(N23+U23+AB23+AK23)*AP23 -> 92.25 | AP23: =(F23-6.5)/4 -> 1.125
A24: ='Escoteiro 22'!C1 -> Escoteiro 22 | B24: Chefe 3 | C24: Patrulha 4 | D24: Caminho | E24: 42026 | F24: =DATEDIF(E24,TODAY(),"M")/12 -> 11 | G24: =datedif(E24,today(),"Y")&" a "&datedif(E24,today(),"YM")&" m" -> 11 a 0 m | H24: =AO24-AM24 -> 92.25 | I24: =INDIRECT("'"&A24&"'!$L$4") -> 0 | J24: =INDIRECT("'"&A24&"'!$L$5") -> 0 | K24: =INDIRECT("'"&A24&"'!$L$6") -> 0 | L24: =INDIRECT("'"&A24&"'!$L$7") -> 0 | M24: =sum(INDIRECT("'"&A24&"'!$K$4:$K$7")) -> 0 | N24: =sum(INDIRECT("'"&A24&"'!$G$4:$G$7")) -> 23 | O24: =average(I24:L24) -> 0 | P24: =INDIRECT("'"&A24&"'!$L$8") -> 0 | Q24: =INDIRECT("'"&A24&"'!$L$9") -> 0 | R24: =INDIRECT("'"&A24&"'!$L$10") -> 0 | S24: =INDIRECT("'"&A24&"'!$L$11") -> 0 | T24: =sum(INDIRECT("'"&A24&"'!$K$8:$K$11")) -> 0 | U24: =sum(INDIRECT("'"&A24&"'!$G$8:$G$11")) -> 29 | V24: =average(P24:S24) -> 0 | W24: =INDIRECT("'"&A24&"'!$L$12") -> 0 | X24: =INDIRECT("'"&A24&"'!$L$13") -> 0 | Y24: =INDIRECT("'"&A24&"'!$L$14") -> 0 | Z24: =INDIRECT("'"&A24&"'!$L$15") -> 0 | AA24: =INDIRECT("'"&A24&"'!$L$16") -> 0 | AB24: =sum(INDIRECT("'"&A24&"'!$K$12:$K$16")) -> 0 | AC24: =sum(INDIRECT("'"&A24&"'!$G$12:$G$16")) -> 28 | AD24: =average(W24:AA24) -> 0 | AE24: =INDIRECT("'"&A24&"'!$L$17") -> 0 | AF24: =INDIRECT("'"&A24&"'!$L$18") -> 0 | AG24: =INDIRECT("'"&A24&"'!$L$19") -> 0 | AH24: =INDIRECT("'"&A24&"'!$L$20") -> 0 | AI24: =INDIRECT("'"&A24&"'!$L$21") -> 0 | AJ24: =sum(INDIRECT("'"&A24&"'!$K$17:$K$21")) -> 0 | AK24: =sum(INDIRECT("'"&A24&"'!$G$17:$G$21")) -> 30 | AL24: =average(AE24:AI24) -> 0 | AM24: =M24+T24+AB24+AJ24 -> 0 | AN24: =AM24/(N24+U24+AC24+AK24) -> 0 | AO24: =(N24+U24+AB24+AK24)*AP24 -> 92.25 | AP24: =(F24-6.5)/4 -> 1.125
A25: ='Escoteiro 23'!C1 -> Escoteiro 23 | B25: Chefe 3 | C25: Patrulha 4 | D25: Caminho | E25: 42027 | F25: =DATEDIF(E25,TODAY(),"M")/12 -> 11 | G25: =datedif(E25,today(),"Y")&" a "&datedif(E25,today(),"YM")&" m" -> 11 a 0 m | H25: =AO25-AM25 -> 92.25 | I25: =INDIRECT("'"&A25&"'!$L$4") -> 0 | J25: =INDIRECT("'"&A25&"'!$L$5") -> 0 | K25: =INDIRECT("'"&A25&"'!$L$6") -> 0 | L25: =INDIRECT("'"&A25&"'!$L$7") -> 0 | M25: =sum(INDIRECT("'"&A25&"'!$K$4:$K$7")) -> 0 | N25: =sum(INDIRECT("'"&A25&"'!$G$4:$G$7")) -> 23 | O25: =average(I25:L25) -> 0 | P25: =INDIRECT("'"&A25&"'!$L$8") -> 0 | Q25: =INDIRECT("'"&A25&"'!$L$9") -> 0 | R25: =INDIRECT("'"&A25&"'!$L$10") -> 0 | S25: =INDIRECT("'"&A25&"'!$L$11") -> 0 | T25: =sum(INDIRECT("'"&A25&"'!$K$8:$K$11")) -> 0 | U25: =sum(INDIRECT("'"&A25&"'!$G$8:$G$11")) -> 29 | V25: =average(P25:S25) -> 0 | W25: =INDIRECT("'"&A25&"'!$L$12") -> 0 | X25: =INDIRECT("'"&A25&"'!$L$13") -> 0 | Y25: =INDIRECT("'"&A25&"'!$L$14") -> 0 | Z25: =INDIRECT("'"&A25&"'!$L$15") -> 0 | AA25: =INDIRECT("'"&A25&"'!$L$16") -> 0 | AB25: =sum(INDIRECT("'"&A25&"'!$K$12:$K$16")) -> 0 | AC25: =sum(INDIRECT("'"&A25&"'!$G$12:$G$16")) -> 28 | AD25: =average(W25:AA25) -> 0 | AE25: =INDIRECT("'"&A25&"'!$L$17") -> 0 | AF25: =INDIRECT("'"&A25&"'!$L$18") -> 0 | AG25: =INDIRECT("'"&A25&"'!$L$19") -> 0 | AH25: =INDIRECT("'"&A25&"'!$L$20") -> 0 | AI25: =INDIRECT("'"&A25&"'!$L$21") -> 0 | AJ25: =sum(INDIRECT("'"&A25&"'!$K$17:$K$21")) -> 0 | AK25: =sum(INDIRECT("'"&A25&"'!$G$17:$G$21")) -> 30 | AL25: =average(AE25:AI25) -> 0 | AM25: =M25+T25+AB25+AJ25 -> 0 | AN25: =AM25/(N25+U25+AC25+AK25) -> 0 | AO25: =(N25+U25+AB25+AK25)*AP25 -> 92.25 | AP25: =(F25-6.5)/4 -> 1.125
A26: ='Escoteiro 24'!C1 -> Escoteiro 24 | B26: Chefe 3 | C26: Patrulha 2 | D26: Caminho | E26: 42028 | F26: =DATEDIF(E26,TODAY(),"M")/12 -> 11 | G26: =datedif(E26,today(),"Y")&" a "&datedif(E26,today(),"YM")&" m" -> 11 a 0 m | H26: =AO26-AM26 -> 92.25 | I26: =INDIRECT("'"&A26&"'!$L$4") -> 0 | J26: =INDIRECT("'"&A26&"'!$L$5") -> 0 | K26: =INDIRECT("'"&A26&"'!$L$6") -> 0 | L26: =INDIRECT("'"&A26&"'!$L$7") -> 0 | M26: =sum(INDIRECT("'"&A26&"'!$K$4:$K$7")) -> 0 | N26: =sum(INDIRECT("'"&A26&"'!$G$4:$G$7")) -> 23 | O26: =average(I26:L26) -> 0 | P26: =INDIRECT("'"&A26&"'!$L$8") -> 0 | Q26: =INDIRECT("'"&A26&"'!$L$9") -> 0 | R26: =INDIRECT("'"&A26&"'!$L$10") -> 0 | S26: =INDIRECT("'"&A26&"'!$L$11") -> 0 | T26: =sum(INDIRECT("'"&A26&"'!$K$8:$K$11")) -> 0 | U26: =sum(INDIRECT("'"&A26&"'!$G$8:$G$11")) -> 29 | V26: =average(P26:S26) -> 0 | W26: =INDIRECT("'"&A26&"'!$L$12") -> 0 | X26: =INDIRECT("'"&A26&"'!$L$13") -> 0 | Y26: =INDIRECT("'"&A26&"'!$L$14") -> 0 | Z26: =INDIRECT("'"&A26&"'!$L$15") -> 0 | AA26: =INDIRECT("'"&A26&"'!$L$16") -> 0 | AB26: =sum(INDIRECT("'"&A26&"'!$K$12:$K$16")) -> 0 | AC26: =sum(INDIRECT("'"&A26&"'!$G$12:$G$16")) -> 28 | AD26: =average(W26:AA26) -> 0 | AE26: =INDIRECT("'"&A26&"'!$L$17") -> 0 | AF26: =INDIRECT("'"&A26&"'!$L$18") -> 0 | AG26: =INDIRECT("'"&A26&"'!$L$19") -> 0 | AH26: =INDIRECT("'"&A26&"'!$L$20") -> 0 | AI26: =INDIRECT("'"&A26&"'!$L$21") -> 0 | AJ26: =sum(INDIRECT("'"&A26&"'!$K$17:$K$21")) -> 0 | AK26: =sum(INDIRECT("'"&A26&"'!$G$17:$G$21")) -> 30 | AL26: =average(AE26:AI26) -> 0 | AM26: =M26+T26+AB26+AJ26 -> 0 | AN26: =AM26/(N26+U26+AC26+AK26) -> 0 | AO26: =(N26+U26+AB26+AK26)*AP26 -> 92.25 | AP26: =(F26-6.5)/4 -> 1.125
A27: ='Escoteiro 24'!C1 -> Escoteiro 24 | B27: Chefe 1 | C27: Patrulha 1 | D27: Caminho | E27: 42029 | F27: =DATEDIF(E27,TODAY(),"M")/12 -> 11 | G27: =datedif(E27,today(),"Y")&" a "&datedif(E27,today(),"YM")&" m" -> 11 a 0 m | H27: =AO27-AM27 -> 92.25 | I27: =INDIRECT("'"&A27&"'!$L$4") -> 0 | J27: =INDIRECT("'"&A27&"'!$L$5") -> 0 | K27: =INDIRECT("'"&A27&"'!$L$6") -> 0 | L27: =INDIRECT("'"&A27&"'!$L$7") -> 0 | M27: =sum(INDIRECT("'"&A27&"'!$K$4:$K$7")) -> 0 | N27: =sum(INDIRECT("'"&A27&"'!$G$4:$G$7")) -> 23 | O27: =average(I27:L27) -> 0 | P27: =INDIRECT("'"&A27&"'!$L$8") -> 0 | Q27: =INDIRECT("'"&A27&"'!$L$9") -> 0 | R27: =INDIRECT("'"&A27&"'!$L$10") -> 0 | S27: =INDIRECT("'"&A27&"'!$L$11") -> 0 | T27: =sum(INDIRECT("'"&A27&"'!$K$8:$K$11")) -> 0 | U27: =sum(INDIRECT("'"&A27&"'!$G$8:$G$11")) -> 29 | V27: =average(P27:S27) -> 0 | W27: =INDIRECT("'"&A27&"'!$L$12") -> 0 | X27: =INDIRECT("'"&A27&"'!$L$13") -> 0 | Y27: =INDIRECT("'"&A27&"'!$L$14") -> 0 | Z27: =INDIRECT("'"&A27&"'!$L$15") -> 0 | AA27: =INDIRECT("'"&A27&"'!$L$16") -> 0 | AB27: =sum(INDIRECT("'"&A27&"'!$K$12:$K$16")) -> 0 | AC27: =sum(INDIRECT("'"&A27&"'!$G$12:$G$16")) -> 28 | AD27: =average(W27:AA27) -> 0 | AE27: =INDIRECT("'"&A27&"'!$L$17") -> 0 | AF27: =INDIRECT("'"&A27&"'!$L$18") -> 0 | AG27: =INDIRECT("'"&A27&"'!$L$19") -> 0 | AH27: =INDIRECT("'"&A27&"'!$L$20") -> 0 | AI27: =INDIRECT("'"&A27&"'!$L$21") -> 0 | AJ27: =sum(INDIRECT("'"&A27&"'!$K$17:$K$21")) -> 0 | AK27: =sum(INDIRECT("'"&A27&"'!$G$17:$G$21")) -> 30 | AL27: =average(AE27:AI27) -> 0 | AM27: =M27+T27+AB27+AJ27 -> 0 | AN27: =AM27/(N27+U27+AC27+AK27) -> 0 | AO27: =(N27+U27+AB27+AK27)*AP27 -> 92.25 | AP27: =(F27-6.5)/4 -> 1.125
A28: ='Escoteiro 26'!C1 -> Escoteiro 26 | B28: Chefe 1 | C28: Patrulha 2 | D28: Caminho | E28: 42030 | F28: =DATEDIF(E28,TODAY(),"M")/12 -> 11 | G28: =datedif(E28,today(),"Y")&" a "&datedif(E28,today(),"YM")&" m" -> 11 a 0 m | H28: =AO28-AM28 -> 92.25 | I28: =INDIRECT("'"&A28&"'!$L$4") -> 0 | J28: =INDIRECT("'"&A28&"'!$L$5") -> 0 | K28: =INDIRECT("'"&A28&"'!$L$6") -> 0 | L28: =INDIRECT("'"&A28&"'!$L$7") -> 0 | M28: =sum(INDIRECT("'"&A28&"'!$K$4:$K$7")) -> 0 | N28: =sum(INDIRECT("'"&A28&"'!$G$4:$G$7")) -> 23 | O28: =average(I28:L28) -> 0 | P28: =INDIRECT("'"&A28&"'!$L$8") -> 0 | Q28: =INDIRECT("'"&A28&"'!$L$9") -> 0 | R28: =INDIRECT("'"&A28&"'!$L$10") -> 0 | S28: =INDIRECT("'"&A28&"'!$L$11") -> 0 | T28: =sum(INDIRECT("'"&A28&"'!$K$8:$K$11")) -> 0 | U28: =sum(INDIRECT("'"&A28&"'!$G$8:$G$11")) -> 29 | V28: =average(P28:S28) -> 0 | W28: =INDIRECT("'"&A28&"'!$L$12") -> 0 | X28: =INDIRECT("'"&A28&"'!$L$13") -> 0 | Y28: =INDIRECT("'"&A28&"'!$L$14") -> 0 | Z28: =INDIRECT("'"&A28&"'!$L$15") -> 0 | AA28: =INDIRECT("'"&A28&"'!$L$16") -> 0 | AB28: =sum(INDIRECT("'"&A28&"'!$K$12:$K$16")) -> 0 | AC28: =sum(INDIRECT("'"&A28&"'!$G$12:$G$16")) -> 28 | AD28: =average(W28:AA28) -> 0 | AE28: =INDIRECT("'"&A28&"'!$L$17") -> 0 | AF28: =INDIRECT("'"&A28&"'!$L$18") -> 0 | AG28: =INDIRECT("'"&A28&"'!$L$19") -> 0 | AH28: =INDIRECT("'"&A28&"'!$L$20") -> 0 | AI28: =INDIRECT("'"&A28&"'!$L$21") -> 0 | AJ28: =sum(INDIRECT("'"&A28&"'!$K$17:$K$21")) -> 0 | AK28: =sum(INDIRECT("'"&A28&"'!$G$17:$G$21")) -> 30 | AL28: =average(AE28:AI28) -> 0 | AM28: =M28+T28+AB28+AJ28 -> 0 | AN28: =AM28/(N28+U28+AC28+AK28) -> 0 | AO28: =(N28+U28+AB28+AK28)*AP28 -> 92.25 | AP28: =(F28-6.5)/4 -> 1.125
A29: ='Escoteiro 27'!C1 -> Escoteiro 27 | B29: Chefe 1 | C29: Patrulha 3 | D29: Caminho | E29: 42031 | F29: =DATEDIF(E29,TODAY(),"M")/12 -> 11 | G29: =datedif(E29,today(),"Y")&" a "&datedif(E29,today(),"YM")&" m" -> 11 a 0 m | H29: =AO29-AM29 -> 92.25 | I29: =INDIRECT("'"&A29&"'!$L$4") -> 0 | J29: =INDIRECT("'"&A29&"'!$L$5") -> 0 | K29: =INDIRECT("'"&A29&"'!$L$6") -> 0 | L29: =INDIRECT("'"&A29&"'!$L$7") -> 0 | M29: =sum(INDIRECT("'"&A29&"'!$K$4:$K$7")) -> 0 | N29: =sum(INDIRECT("'"&A29&"'!$G$4:$G$7")) -> 23 | O29: =average(I29:L29) -> 0 | P29: =INDIRECT("'"&A29&"'!$L$8") -> 0 | Q29: =INDIRECT("'"&A29&"'!$L$9") -> 0 | R29: =INDIRECT("'"&A29&"'!$L$10") -> 0 | S29: =INDIRECT("'"&A29&"'!$L$11") -> 0 | T29: =sum(INDIRECT("'"&A29&"'!$K$8:$K$11")) -> 0 | U29: =sum(INDIRECT("'"&A29&"'!$G$8:$G$11")) -> 29 | V29: =average(P29:S29) -> 0 | W29: =INDIRECT("'"&A29&"'!$L$12") -> 0 | X29: =INDIRECT("'"&A29&"'!$L$13") -> 0 | Y29: =INDIRECT("'"&A29&"'!$L$14") -> 0 | Z29: =INDIRECT("'"&A29&"'!$L$15") -> 0 | AA29: =INDIRECT("'"&A29&"'!$L$16") -> 0 | AB29: =sum(INDIRECT("'"&A29&"'!$K$12:$K$16")) -> 0 | AC29: =sum(INDIRECT("'"&A29&"'!$G$12:$G$16")) -> 28 | AD29: =average(W29:AA29) -> 0 | AE29: =INDIRECT("'"&A29&"'!$L$17") -> 0 | AF29: =INDIRECT("'"&A29&"'!$L$18") -> 0 | AG29: =INDIRECT("'"&A29&"'!$L$19") -> 0 | AH29: =INDIRECT("'"&A29&"'!$L$20") -> 0 | AI29: =INDIRECT("'"&A29&"'!$L$21") -> 0 | AJ29: =sum(INDIRECT("'"&A29&"'!$K$17:$K$21")) -> 0 | AK29: =sum(INDIRECT("'"&A29&"'!$G$17:$G$21")) -> 30 | AL29: =average(AE29:AI29) -> 0 | AM29: =M29+T29+AB29+AJ29 -> 0 | AN29: =AM29/(N29+U29+AC29+AK29) -> 0 | AO29: =(N29+U29+AB29+AK29)*AP29 -> 92.25 | AP29: =(F29-6.5)/4 -> 1.125
A30: ='Escoteiro 28'!C1 -> Escoteiro 28 | B30: Chefe 1 | C30: Patrulha 1 | D30: Caminho | E30: 42032 | F30: =DATEDIF(E30,TODAY(),"M")/12 -> 11 | G30: =datedif(E30,today(),"Y")&" a "&datedif(E30,today(),"YM")&" m" -> 11 a 0 m | H30: =AO30-AM30 -> 92.25 | I30: =INDIRECT("'"&A30&"'!$L$4") -> 0 | J30: =INDIRECT("'"&A30&"'!$L$5") -> 0 | K30: =INDIRECT("'"&A30&"'!$L$6") -> 0 | L30: =INDIRECT("'"&A30&"'!$L$7") -> 0 | M30: =sum(INDIRECT("'"&A30&"'!$K$4:$K$7")) -> 0 | N30: =sum(INDIRECT("'"&A30&"'!$G$4:$G$7")) -> 23 | O30: =average(I30:L30) -> 0 | P30: =INDIRECT("'"&A30&"'!$L$8") -> 0 | Q30: =INDIRECT("'"&A30&"'!$L$9") -> 0 | R30: =INDIRECT("'"&A30&"'!$L$10") -> 0 | S30: =INDIRECT("'"&A30&"'!$L$11") -> 0 | T30: =sum(INDIRECT("'"&A30&"'!$K$8:$K$11")) -> 0 | U30: =sum(INDIRECT("'"&A30&"'!$G$8:$G$11")) -> 29 | V30: =average(P30:S30) -> 0 | W30: =INDIRECT("'"&A30&"'!$L$12") -> 0 | X30: =INDIRECT("'"&A30&"'!$L$13") -> 0 | Y30: =INDIRECT("'"&A30&"'!$L$14") -> 0 | Z30: =INDIRECT("'"&A30&"'!$L$15") -> 0 | AA30: =INDIRECT("'"&A30&"'!$L$16") -> 0 | AB30: =sum(INDIRECT("'"&A30&"'!$K$12:$K$16")) -> 0 | AC30: =sum(INDIRECT("'"&A30&"'!$G$12:$G$16")) -> 28 | AD30: =average(W30:AA30) -> 0 | AE30: =INDIRECT("'"&A30&"'!$L$17") -> 0 | AF30: =INDIRECT("'"&A30&"'!$L$18") -> 0 | AG30: =INDIRECT("'"&A30&"'!$L$19") -> 0 | AH30: =INDIRECT("'"&A30&"'!$L$20") -> 0 | AI30: =INDIRECT("'"&A30&"'!$L$21") -> 0 | AJ30: =sum(INDIRECT("'"&A30&"'!$K$17:$K$21")) -> 0 | AK30: =sum(INDIRECT("'"&A30&"'!$G$17:$G$21")) -> 30 | AL30: =average(AE30:AI30) -> 0 | AM30: =M30+T30+AB30+AJ30 -> 0 | AN30: =AM30/(N30+U30+AC30+AK30) -> 0 | AO30: =(N30+U30+AB30+AK30)*AP30 -> 92.25 | AP30: =(F30-6.5)/4 -> 1.125
A31: ='Escoteiro 29'!C1 -> Escoteiro 29 | B31: Chefe 1 | C31: Patrulha 2 | D31: Caminho | E31: 42033 | F31: =DATEDIF(E31,TODAY(),"M")/12 -> 11 | G31: =datedif(E31,today(),"Y")&" a "&datedif(E31,today(),"YM")&" m" -> 11 a 0 m | H31: =AO31-AM31 -> 92.25 | I31: =INDIRECT("'"&A31&"'!$L$4") -> 0 | J31: =INDIRECT("'"&A31&"'!$L$5") -> 0 | K31: =INDIRECT("'"&A31&"'!$L$6") -> 0 | L31: =INDIRECT("'"&A31&"'!$L$7") -> 0 | M31: =sum(INDIRECT("'"&A31&"'!$K$4:$K$7")) -> 0 | N31: =sum(INDIRECT("'"&A31&"'!$G$4:$G$7")) -> 23 | O31: =average(I31:L31) -> 0 | P31: =INDIRECT("'"&A31&"'!$L$8") -> 0 | Q31: =INDIRECT("'"&A31&"'!$L$9") -> 0 | R31: =INDIRECT("'"&A31&"'!$L$10") -> 0 | S31: =INDIRECT("'"&A31&"'!$L$11") -> 0 | T31: =sum(INDIRECT("'"&A31&"'!$K$8:$K$11")) -> 0 | U31: =sum(INDIRECT("'"&A31&"'!$G$8:$G$11")) -> 29 | V31: =average(P31:S31) -> 0 | W31: =INDIRECT("'"&A31&"'!$L$12") -> 0 | X31: =INDIRECT("'"&A31&"'!$L$13") -> 0 | Y31: =INDIRECT("'"&A31&"'!$L$14") -> 0 | Z31: =INDIRECT("'"&A31&"'!$L$15") -> 0 | AA31: =INDIRECT("'"&A31&"'!$L$16") -> 0 | AB31: =sum(INDIRECT("'"&A31&"'!$K$12:$K$16")) -> 0 | AC31: =sum(INDIRECT("'"&A31&"'!$G$12:$G$16")) -> 28 | AD31: =average(W31:AA31) -> 0 | AE31: =INDIRECT("'"&A31&"'!$L$17") -> 0 | AF31: =INDIRECT("'"&A31&"'!$L$18") -> 0 | AG31: =INDIRECT("'"&A31&"'!$L$19") -> 0 | AH31: =INDIRECT("'"&A31&"'!$L$20") -> 0 | AI31: =INDIRECT("'"&A31&"'!$L$21") -> 0 | AJ31: =sum(INDIRECT("'"&A31&"'!$K$17:$K$21")) -> 0 | AK31: =sum(INDIRECT("'"&A31&"'!$G$17:$G$21")) -> 30 | AL31: =average(AE31:AI31) -> 0 | AM31: =M31+T31+AB31+AJ31 -> 0 | AN31: =AM31/(N31+U31+AC31+AK31) -> 0 | AO31: =(N31+U31+AB31+AK31)*AP31 -> 92.25 | AP31: =(F31-6.5)/4 -> 1.125
A32: ='Escoteiro 30'!C1 -> Escoteiro 30 | B32: Chefe 2 | C32: Patrulha 4 | D32: Caminho | E32: 42034 | F32: =DATEDIF(E32,TODAY(),"M")/12 -> 11 | G32: =datedif(E32,today(),"Y")&" a "&datedif(E32,today(),"YM")&" m" -> 11 a 0 m | H32: =AO32-AM32 -> 92.25 | I32: =INDIRECT("'"&A32&"'!$L$4") -> 0 | J32: =INDIRECT("'"&A32&"'!$L$5") -> 0 | K32: =INDIRECT("'"&A32&"'!$L$6") -> 0 | L32: =INDIRECT("'"&A32&"'!$L$7") -> 0 | M32: =sum(INDIRECT("'"&A32&"'!$K$4:$K$7")) -> 0 | N32: =sum(INDIRECT("'"&A32&"'!$G$4:$G$7")) -> 23 | O32: =average(I32:L32) -> 0 | P32: =INDIRECT("'"&A32&"'!$L$8") -> 0 | Q32: =INDIRECT("'"&A32&"'!$L$9") -> 0 | R32: =INDIRECT("'"&A32&"'!$L$10") -> 0 | S32: =INDIRECT("'"&A32&"'!$L$11") -> 0 | T32: =sum(INDIRECT("'"&A32&"'!$K$8:$K$11")) -> 0 | U32: =sum(INDIRECT("'"&A32&"'!$G$8:$G$11")) -> 29 | V32: =average(P32:S32) -> 0 | W32: =INDIRECT("'"&A32&"'!$L$12") -> 0 | X32: =INDIRECT("'"&A32&"'!$L$13") -> 0 | Y32: =INDIRECT("'"&A32&"'!$L$14") -> 0 | Z32: =INDIRECT("'"&A32&"'!$L$15") -> 0 | AA32: =INDIRECT("'"&A32&"'!$L$16") -> 0 | AB32: =sum(INDIRECT("'"&A32&"'!$K$12:$K$16")) -> 0 | AC32: =sum(INDIRECT("'"&A32&"'!$G$12:$G$16")) -> 28 | AD32: =average(W32:AA32) -> 0 | AE32: =INDIRECT("'"&A32&"'!$L$17") -> 0 | AF32: =INDIRECT("'"&A32&"'!$L$18") -> 0 | AG32: =INDIRECT("'"&A32&"'!$L$19") -> 0 | AH32: =INDIRECT("'"&A32&"'!$L$20") -> 0 | AI32: =INDIRECT("'"&A32&"'!$L$21") -> 0 | AJ32: =sum(INDIRECT("'"&A32&"'!$K$17:$K$21")) -> 0 | AK32: =sum(INDIRECT("'"&A32&"'!$G$17:$G$21")) -> 30 | AL32: =average(AE32:AI32) -> 0 | AM32: =M32+T32+AB32+AJ32 -> 0 | AN32: =AM32/(N32+U32+AC32+AK32) -> 0 | AO32: =(N32+U32+AB32+AK32)*AP32 -> 92.25 | AP32: =(F32-6.5)/4 -> 1.125
A33: ='Escoteiro 31'!C1 -> Escoteiro 31 | B33: Chefe 2 | C33: Patrulha 3 | D33: Caminho | E33: 42035 | F33: =DATEDIF(E33,TODAY(),"M")/12 -> 11 | G33: =datedif(E33,today(),"Y")&" a "&datedif(E33,today(),"YM")&" m" -> 11 a 0 m | H33: =AO33-AM33 -> 92.25 | I33: =INDIRECT("'"&A33&"'!$L$4") -> 0 | J33: =INDIRECT("'"&A33&"'!$L$5") -> 0 | K33: =INDIRECT("'"&A33&"'!$L$6") -> 0 | L33: =INDIRECT("'"&A33&"'!$L$7") -> 0 | M33: =sum(INDIRECT("'"&A33&"'!$K$4:$K$7")) -> 0 | N33: =sum(INDIRECT("'"&A33&"'!$G$4:$G$7")) -> 23 | O33: =average(I33:L33) -> 0 | P33: =INDIRECT("'"&A33&"'!$L$8") -> 0 | Q33: =INDIRECT("'"&A33&"'!$L$9") -> 0 | R33: =INDIRECT("'"&A33&"'!$L$10") -> 0 | S33: =INDIRECT("'"&A33&"'!$L$11") -> 0 | T33: =sum(INDIRECT("'"&A33&"'!$K$8:$K$11")) -> 0 | U33: =sum(INDIRECT("'"&A33&"'!$G$8:$G$11")) -> 29 | V33: =average(P33:S33) -> 0 | W33: =INDIRECT("'"&A33&"'!$L$12") -> 0 | X33: =INDIRECT("'"&A33&"'!$L$13") -> 0 | Y33: =INDIRECT("'"&A33&"'!$L$14") -> 0 | Z33: =INDIRECT("'"&A33&"'!$L$15") -> 0 | AA33: =INDIRECT("'"&A33&"'!$L$16") -> 0 | AB33: =sum(INDIRECT("'"&A33&"'!$K$12:$K$16")) -> 0 | AC33: =sum(INDIRECT("'"&A33&"'!$G$12:$G$16")) -> 28 | AD33: =average(W33:AA33) -> 0 | AE33: =INDIRECT("'"&A33&"'!$L$17") -> 0 | AF33: =INDIRECT("'"&A33&"'!$L$18") -> 0 | AG33: =INDIRECT("'"&A33&"'!$L$19") -> 0 | AH33: =INDIRECT("'"&A33&"'!$L$20") -> 0 | AI33: =INDIRECT("'"&A33&"'!$L$21") -> 0 | AJ33: =sum(INDIRECT("'"&A33&"'!$K$17:$K$21")) -> 0 | AK33: =sum(INDIRECT("'"&A33&"'!$G$17:$G$21")) -> 30 | AL33: =average(AE33:AI33) -> 0 | AM33: =M33+T33+AB33+AJ33 -> 0 | AN33: =AM33/(N33+U33+AC33+AK33) -> 0 | AO33: =(N33+U33+AB33+AK33)*AP33 -> 92.25 | AP33: =(F33-6.5)/4 -> 1.125
A34: ='Escoteiro 32'!C1 -> Escoteiro 32 | B34: Chefe 2 | C34: Patrulha 1 | D34: Caminho | E34: 42036 | F34: =DATEDIF(E34,TODAY(),"M")/12 -> 11 | G34: =datedif(E34,today(),"Y")&" a "&datedif(E34,today(),"YM")&" m" -> 11 a 0 m | H34: =AO34-AM34 -> 92.25 | I34: =INDIRECT("'"&A34&"'!$L$4") -> 0 | J34: =INDIRECT("'"&A34&"'!$L$5") -> 0 | K34: =INDIRECT("'"&A34&"'!$L$6") -> 0 | L34: =INDIRECT("'"&A34&"'!$L$7") -> 0 | M34: =sum(INDIRECT("'"&A34&"'!$K$4:$K$7")) -> 0 | N34: =sum(INDIRECT("'"&A34&"'!$G$4:$G$7")) -> 23 | O34: =average(I34:L34) -> 0 | P34: =INDIRECT("'"&A34&"'!$L$8") -> 0 | Q34: =INDIRECT("'"&A34&"'!$L$9") -> 0 | R34: =INDIRECT("'"&A34&"'!$L$10") -> 0 | S34: =INDIRECT("'"&A34&"'!$L$11") -> 0 | T34: =sum(INDIRECT("'"&A34&"'!$K$8:$K$11")) -> 0 | U34: =sum(INDIRECT("'"&A34&"'!$G$8:$G$11")) -> 29 | V34: =average(P34:S34) -> 0 | W34: =INDIRECT("'"&A34&"'!$L$12") -> 0 | X34: =INDIRECT("'"&A34&"'!$L$13") -> 0 | Y34: =INDIRECT("'"&A34&"'!$L$14") -> 0 | Z34: =INDIRECT("'"&A34&"'!$L$15") -> 0 | AA34: =INDIRECT("'"&A34&"'!$L$16") -> 0 | AB34: =sum(INDIRECT("'"&A34&"'!$K$12:$K$16")) -> 0 | AC34: =sum(INDIRECT("'"&A34&"'!$G$12:$G$16")) -> 28 | AD34: =average(W34:AA34) -> 0 | AE34: =INDIRECT("'"&A34&"'!$L$17") -> 0 | AF34: =INDIRECT("'"&A34&"'!$L$18") -> 0 | AG34: =INDIRECT("'"&A34&"'!$L$19") -> 0 | AH34: =INDIRECT("'"&A34&"'!$L$20") -> 0 | AI34: =INDIRECT("'"&A34&"'!$L$21") -> 0 | AJ34: =sum(INDIRECT("'"&A34&"'!$K$17:$K$21")) -> 0 | AK34: =sum(INDIRECT("'"&A34&"'!$G$17:$G$21")) -> 30 | AL34: =average(AE34:AI34) -> 0 | AM34: =M34+T34+AB34+AJ34 -> 0 | AN34: =AM34/(N34+U34+AC34+AK34) -> 0 | AO34: =(N34+U34+AB34+AK34)*AP34 -> 92.25 | AP34: =(F34-6.5)/4 -> 1.125
A35: ='Escoteiro 33'!C1 -> Escoteiro 33 | B35: Chefe 2 | C35: Patrulha 3 | D35: Caminho | E35: 42037 | F35: =DATEDIF(E35,TODAY(),"M")/12 -> 11 | G35: =datedif(E35,today(),"Y")&" a "&datedif(E35,today(),"YM")&" m" -> 11 a 0 m | H35: =AO35-AM35 -> 92.25 | I35: =INDIRECT("'"&A35&"'!$L$4") -> 0 | J35: =INDIRECT("'"&A35&"'!$L$5") -> 0 | K35: =INDIRECT("'"&A35&"'!$L$6") -> 0 | L35: =INDIRECT("'"&A35&"'!$L$7") -> 0 | M35: =sum(INDIRECT("'"&A35&"'!$K$4:$K$7")) -> 0 | N35: =sum(INDIRECT("'"&A35&"'!$G$4:$G$7")) -> 23 | O35: =average(I35:L35) -> 0 | P35: =INDIRECT("'"&A35&"'!$L$8") -> 0 | Q35: =INDIRECT("'"&A35&"'!$L$9") -> 0 | R35: =INDIRECT("'"&A35&"'!$L$10") -> 0 | S35: =INDIRECT("'"&A35&"'!$L$11") -> 0 | T35: =sum(INDIRECT("'"&A35&"'!$K$8:$K$11")) -> 0 | U35: =sum(INDIRECT("'"&A35&"'!$G$8:$G$11")) -> 29 | V35: =average(P35:S35) -> 0 | W35: =INDIRECT("'"&A35&"'!$L$12") -> 0 | X35: =INDIRECT("'"&A35&"'!$L$13") -> 0 | Y35: =INDIRECT("'"&A35&"'!$L$14") -> 0 | Z35: =INDIRECT("'"&A35&"'!$L$15") -> 0 | AA35: =INDIRECT("'"&A35&"'!$L$16") -> 0 | AB35: =sum(INDIRECT("'"&A35&"'!$K$12:$K$16")) -> 0 | AC35: =sum(INDIRECT("'"&A35&"'!$G$12:$G$16")) -> 28 | AD35: =average(W35:AA35) -> 0 | AE35: =INDIRECT("'"&A35&"'!$L$17") -> 0 | AF35: =INDIRECT("'"&A35&"'!$L$18") -> 0 | AG35: =INDIRECT("'"&A35&"'!$L$19") -> 0 | AH35: =INDIRECT("'"&A35&"'!$L$20") -> 0 | AI35: =INDIRECT("'"&A35&"'!$L$21") -> 0 | AJ35: =sum(INDIRECT("'"&A35&"'!$K$17:$K$21")) -> 0 | AK35: =sum(INDIRECT("'"&A35&"'!$G$17:$G$21")) -> 30 | AL35: =average(AE35:AI35) -> 0 | AM35: =M35+T35+AB35+AJ35 -> 0 | AN35: =AM35/(N35+U35+AC35+AK35) -> 0 | AO35: =(N35+U35+AB35+AK35)*AP35 -> 92.25 | AP35: =(F35-6.5)/4 -> 1.125
A36: ='Escoteiro 34'!C1 -> Escoteiro 34 | B36: Chefe 3 | C36: Patrulha 4 | D36: Caminho | E36: 42038 | F36: =DATEDIF(E36,TODAY(),"M")/12 -> 11 | G36: =datedif(E36,today(),"Y")&" a "&datedif(E36,today(),"YM")&" m" -> 11 a 0 m | H36: =AO36-AM36 -> 92.25 | I36: =INDIRECT("'"&A36&"'!$L$4") -> 0 | J36: =INDIRECT("'"&A36&"'!$L$5") -> 0 | K36: =INDIRECT("'"&A36&"'!$L$6") -> 0 | L36: =INDIRECT("'"&A36&"'!$L$7") -> 0 | M36: =sum(INDIRECT("'"&A36&"'!$K$4:$K$7")) -> 0 | N36: =sum(INDIRECT("'"&A36&"'!$G$4:$G$7")) -> 23 | O36: =average(I36:L36) -> 0 | P36: =INDIRECT("'"&A36&"'!$L$8") -> 0 | Q36: =INDIRECT("'"&A36&"'!$L$9") -> 0 | R36: =INDIRECT("'"&A36&"'!$L$10") -> 0 | S36: =INDIRECT("'"&A36&"'!$L$11") -> 0 | T36: =sum(INDIRECT("'"&A36&"'!$K$8:$K$11")) -> 0 | U36: =sum(INDIRECT("'"&A36&"'!$G$8:$G$11")) -> 29 | V36: =average(P36:S36) -> 0 | W36: =INDIRECT("'"&A36&"'!$L$12") -> 0 | X36: =INDIRECT("'"&A36&"'!$L$13") -> 0 | Y36: =INDIRECT("'"&A36&"'!$L$14") -> 0 | Z36: =INDIRECT("'"&A36&"'!$L$15") -> 0 | AA36: =INDIRECT("'"&A36&"'!$L$16") -> 0 | AB36: =sum(INDIRECT("'"&A36&"'!$K$12:$K$16")) -> 0 | AC36: =sum(INDIRECT("'"&A36&"'!$G$12:$G$16")) -> 28 | AD36: =average(W36:AA36) -> 0 | AE36: =INDIRECT("'"&A36&"'!$L$17") -> 0 | AF36: =INDIRECT("'"&A36&"'!$L$18") -> 0 | AG36: =INDIRECT("'"&A36&"'!$L$19") -> 0 | AH36: =INDIRECT("'"&A36&"'!$L$20") -> 0 | AI36: =INDIRECT("'"&A36&"'!$L$21") -> 0 | AJ36: =sum(INDIRECT("'"&A36&"'!$K$17:$K$21")) -> 0 | AK36: =sum(INDIRECT("'"&A36&"'!$G$17:$G$21")) -> 30 | AL36: =average(AE36:AI36) -> 0 | AM36: =M36+T36+AB36+AJ36 -> 0 | AN36: =AM36/(N36+U36+AC36+AK36) -> 0 | AO36: =(N36+U36+AB36+AK36)*AP36 -> 92.25 | AP36: =(F36-6.5)/4 -> 1.125
A37: ='Escoteiro 35'!C1 -> Escoteiro 35 | B37: Chefe 3 | C37: Patrulha 4 | D37: Caminho | E37: 42039 | F37: =DATEDIF(E37,TODAY(),"M")/12 -> 11 | G37: =datedif(E37,today(),"Y")&" a "&datedif(E37,today(),"YM")&" m" -> 11 a 0 m | H37: =AO37-AM37 -> 92.25 | I37: =INDIRECT("'"&A37&"'!$L$4") -> 0 | J37: =INDIRECT("'"&A37&"'!$L$5") -> 0 | K37: =INDIRECT("'"&A37&"'!$L$6") -> 0 | L37: =INDIRECT("'"&A37&"'!$L$7") -> 0 | M37: =sum(INDIRECT("'"&A37&"'!$K$4:$K$7")) -> 0 | N37: =sum(INDIRECT("'"&A37&"'!$G$4:$G$7")) -> 23 | O37: =average(I37:L37) -> 0 | P37: =INDIRECT("'"&A37&"'!$L$8") -> 0 | Q37: =INDIRECT("'"&A37&"'!$L$9") -> 0 | R37: =INDIRECT("'"&A37&"'!$L$10") -> 0 | S37: =INDIRECT("'"&A37&"'!$L$11") -> 0 | T37: =sum(INDIRECT("'"&A37&"'!$K$8:$K$11")) -> 0 | U37: =sum(INDIRECT("'"&A37&"'!$G$8:$G$11")) -> 29 | V37: =average(P37:S37) -> 0 | W37: =INDIRECT("'"&A37&"'!$L$12") -> 0 | X37: =INDIRECT("'"&A37&"'!$L$13") -> 0 | Y37: =INDIRECT("'"&A37&"'!$L$14") -> 0 | Z37: =INDIRECT("'"&A37&"'!$L$15") -> 0 | AA37: =INDIRECT("'"&A37&"'!$L$16") -> 0 | AB37: =sum(INDIRECT("'"&A37&"'!$K$12:$K$16")) -> 0 | AC37: =sum(INDIRECT("'"&A37&"'!$G$12:$G$16")) -> 28 | AD37: =average(W37:AA37) -> 0 | AE37: =INDIRECT("'"&A37&"'!$L$17") -> 0 | AF37: =INDIRECT("'"&A37&"'!$L$18") -> 0 | AG37: =INDIRECT("'"&A37&"'!$L$19") -> 0 | AH37: =INDIRECT("'"&A37&"'!$L$20") -> 0 | AI37: =INDIRECT("'"&A37&"'!$L$21") -> 0 | AJ37: =sum(INDIRECT("'"&A37&"'!$K$17:$K$21")) -> 0 | AK37: =sum(INDIRECT("'"&A37&"'!$G$17:$G$21")) -> 30 | AL37: =average(AE37:AI37) -> 0 | AM37: =M37+T37+AB37+AJ37 -> 0 | AN37: =AM37/(N37+U37+AC37+AK37) -> 0 | AO37: =(N37+U37+AB37+AK37)*AP37 -> 92.25 | AP37: =(F37-6.5)/4 -> 1.125
